<?xml version="1.0" encoding="utf-8"?>
<!-- =================================================================================== -->
<!-- |    This document was autogenerated by xacro from main.xacro                     | -->
<!-- |    EDITING THIS FILE BY HAND IS NOT RECOMMENDED                                 | -->
<!-- =================================================================================== -->
<robot name="the_Walking_thread">
  <link name="base_link">
    <visual>
      <geometry>
        <box size="0.3 0.15 0.08"/>
      </geometry>
      <origin xyz="0 0 0"/>
    </visual>
    <collision>
      <geometry>
        <box size="0.3 0.15 0.08"/>
      </geometry>
    </collision>
    <inertial>
      <mass value="10"/>
      <inertia ixx="0.2" ixy="0.2" ixz="0.2" iyy="0.2" iyz="0.2" izz="0.2"/>
    </inertial>
  </link>
  <!-- coax link definition -->
  <link name="left_front_coax">
    <visual>
      <geometry>
        <cylinder length="0.01" radius="0.025"/>
      </geometry>
      <origin rpy="0 0 1.57079632679" xyz="0 0 -0.005"/>
    </visual>
    <collision>
      <geometry>
        <sphere radius="0.025"/>
      </geometry>
      <origin rpy="0 0 0" xyz="0 0 --0.0025"/>
    </collision>
    <inertial>
      <mass value="0.2"/>
      <inertia ixx="0.2" ixy="0.2" ixz="0.2" iyy="0.2" iyz="0.2" izz="0.2"/>
    </inertial>
  </link>
  <!-- femur link definition -->
  <link name="left_front_femur">
    <visual>
      <geometry>
        <cylinder length="0.15" radius="0.025"/>
      </geometry>
      <origin rpy="0 0 0" xyz="0 0 -0.075"/>
    </visual>
    <collision>
      <geometry>
        <sphere radius="0.025"/>
      </geometry>
      <origin rpy="0 0 0" xyz="0 0 -0.1375"/>
    </collision>
    <inertial>
      <mass value="0.2"/>
      <inertia ixx="0.2" ixy="0.2" ixz="0.2" iyy="0.2" iyz="0.2" izz="0.2"/>
    </inertial>
  </link>
  <!-- tibia link definition -->
  <link name="left_front_tibia">
    <visual>
      <geometry>
        <cylinder length="0.15" radius="0.025"/>
      </geometry>
      <origin rpy="0 0 0" xyz="0 0 -0.075"/>
    </visual>
    <collision>
      <geometry>
        <sphere radius="0.025"/>
      </geometry>
      <origin rpy="0 0 0" xyz="0 0 -0.1375"/>
    </collision>
    <inertial>
      <mass value="0.2"/>
      <inertia ixx="0.2" ixy="0.2" ixz="0.2" iyy="0.2" iyz="0.2" izz="0.2"/>
    </inertial>
  </link>
  <!-- joint 1 definition -->
  <joint name="left_front_coax_joint" type="revolute">
    <parent link="base_link"/>
    <child link="left_front_coax"/>
    <axis xyz="0 -1 0"/>
    <limit effort="0.2" lower="-0.785398163397" upper="0.785398163397" velocity="0.2"/>
    <origin rpy="1.57079632679 0 0" xyz="0.15 0.075 0"/>
  </joint>
  <!-- joint 2 definition -->
  <joint name="left_front_femur_joint" type="revolute">
    <parent link="left_front_coax"/>
    <child link="left_front_femur"/>
    <axis xyz="1 0 0"/>
    <limit effort="0.2" lower="-0.785398163397" upper="0.785398163397" velocity="0.2"/>
    <origin rpy="0 0 0" xyz="0 0 -0.01"/>
  </joint>
  <!-- joint 3 definition -->
  <joint name="left_front_tibia_joint" type="revolute">
    <parent link="left_front_femur"/>
    <child link="left_front_tibia"/>
    <axis xyz="1 0 0"/>
    <limit effort="0.2" lower="-2.35619449019" upper="0.0" velocity="0.2"/>
    <origin rpy="0 0 0" xyz="0 0 -0.15"/>
  </joint>
  <!-- coax link definition -->
  <link name="left_central_coax">
    <visual>
      <geometry>
        <cylinder length="0.01" radius="0.025"/>
      </geometry>
      <origin rpy="0 0 1.57079632679" xyz="0 0 -0.005"/>
    </visual>
    <collision>
      <geometry>
        <sphere radius="0.025"/>
      </geometry>
      <origin rpy="0 0 0" xyz="0 0 --0.0025"/>
    </collision>
    <inertial>
      <mass value="0.2"/>
      <inertia ixx="0.2" ixy="0.2" ixz="0.2" iyy="0.2" iyz="0.2" izz="0.2"/>
    </inertial>
  </link>
  <!-- femur link definition -->
  <link name="left_central_femur">
    <visual>
      <geometry>
        <cylinder length="0.15" radius="0.025"/>
      </geometry>
      <origin rpy="0 0 0" xyz="0 0 -0.075"/>
    </visual>
    <collision>
      <geometry>
        <sphere radius="0.025"/>
      </geometry>
      <origin rpy="0 0 0" xyz="0 0 -0.1375"/>
    </collision>
    <inertial>
      <mass value="0.2"/>
      <inertia ixx="0.2" ixy="0.2" ixz="0.2" iyy="0.2" iyz="0.2" izz="0.2"/>
    </inertial>
  </link>
  <!-- tibia link definition -->
  <link name="left_central_tibia">
    <visual>
      <geometry>
        <cylinder length="0.15" radius="0.025"/>
      </geometry>
      <origin rpy="0 0 0" xyz="0 0 -0.075"/>
    </visual>
    <collision>
      <geometry>
        <sphere radius="0.025"/>
      </geometry>
      <origin rpy="0 0 0" xyz="0 0 -0.1375"/>
    </collision>
    <inertial>
      <mass value="0.2"/>
      <inertia ixx="0.2" ixy="0.2" ixz="0.2" iyy="0.2" iyz="0.2" izz="0.2"/>
    </inertial>
  </link>
  <!-- joint 1 definition -->
  <joint name="left_central_coax_joint" type="revolute">
    <parent link="base_link"/>
    <child link="left_central_coax"/>
    <axis xyz="0 -1 0"/>
    <limit effort="0.2" lower="-0.785398163397" upper="0.785398163397" velocity="0.2"/>
    <origin rpy="1.57079632679 0 0" xyz="0 0.075 0"/>
  </joint>
  <!-- joint 2 definition -->
  <joint name="left_central_femur_joint" type="revolute">
    <parent link="left_central_coax"/>
    <child link="left_central_femur"/>
    <axis xyz="1 0 0"/>
    <limit effort="0.2" lower="-0.785398163397" upper="0.785398163397" velocity="0.2"/>
    <origin rpy="0 0 0" xyz="0 0 -0.01"/>
  </joint>
  <!-- joint 3 definition -->
  <joint name="left_central_tibia_joint" type="revolute">
    <parent link="left_central_femur"/>
    <child link="left_central_tibia"/>
    <axis xyz="1 0 0"/>
    <limit effort="0.2" lower="-2.35619449019" upper="0.0" velocity="0.2"/>
    <origin rpy="0 0 0" xyz="0 0 -0.15"/>
  </joint>
  <!-- coax link definition -->
  <link name="left_rear_coax">
    <visual>
      <geometry>
        <cylinder length="0.01" radius="0.025"/>
      </geometry>
      <origin rpy="0 0 1.57079632679" xyz="0 0 -0.005"/>
    </visual>
    <collision>
      <geometry>
        <sphere radius="0.025"/>
      </geometry>
      <origin rpy="0 0 0" xyz="0 0 --0.0025"/>
    </collision>
    <inertial>
      <mass value="0.2"/>
      <inertia ixx="0.2" ixy="0.2" ixz="0.2" iyy="0.2" iyz="0.2" izz="0.2"/>
    </inertial>
  </link>
  <!-- femur link definition -->
  <link name="left_rear_femur">
    <visual>
      <geometry>
        <cylinder length="0.15" radius="0.025"/>
      </geometry>
      <origin rpy="0 0 0" xyz="0 0 -0.075"/>
    </visual>
    <collision>
      <geometry>
        <sphere radius="0.025"/>
      </geometry>
      <origin rpy="0 0 0" xyz="0 0 -0.1375"/>
    </collision>
    <inertial>
      <mass value="0.2"/>
      <inertia ixx="0.2" ixy="0.2" ixz="0.2" iyy="0.2" iyz="0.2" izz="0.2"/>
    </inertial>
  </link>
  <!-- tibia link definition -->
  <link name="left_rear_tibia">
    <visual>
      <geometry>
        <cylinder length="0.15" radius="0.025"/>
      </geometry>
      <origin rpy="0 0 0" xyz="0 0 -0.075"/>
    </visual>
    <collision>
      <geometry>
        <sphere radius="0.025"/>
      </geometry>
      <origin rpy="0 0 0" xyz="0 0 -0.1375"/>
    </collision>
    <inertial>
      <mass value="0.2"/>
      <inertia ixx="0.2" ixy="0.2" ixz="0.2" iyy="0.2" iyz="0.2" izz="0.2"/>
    </inertial>
  </link>
  <!-- joint 1 definition -->
  <joint name="left_rear_coax_joint" type="revolute">
    <parent link="base_link"/>
    <child link="left_rear_coax"/>
    <axis xyz="0 -1 0"/>
    <limit effort="0.2" lower="-0.785398163397" upper="0.785398163397" velocity="0.2"/>
    <origin rpy="1.57079632679 0 0" xyz="-0.15 0.075 0"/>
  </joint>
  <!-- joint 2 definition -->
  <joint name="left_rear_femur_joint" type="revolute">
    <parent link="left_rear_coax"/>
    <child link="left_rear_femur"/>
    <axis xyz="1 0 0"/>
    <limit effort="0.2" lower="-0.785398163397" upper="0.785398163397" velocity="0.2"/>
    <origin rpy="0 0 0" xyz="0 0 -0.01"/>
  </joint>
  <!-- joint 3 definition -->
  <joint name="left_rear_tibia_joint" type="revolute">
    <parent link="left_rear_femur"/>
    <child link="left_rear_tibia"/>
    <axis xyz="1 0 0"/>
    <limit effort="0.2" lower="-2.35619449019" upper="0.0" velocity="0.2"/>
    <origin rpy="0 0 0" xyz="0 0 -0.15"/>
  </joint>
  <!-- coax link definition -->
  <link name="right_front_coax">
    <visual>
      <geometry>
        <cylinder length="0.01" radius="0.025"/>
      </geometry>
      <origin rpy="0 0 1.57079632679" xyz="0 0 -0.005"/>
    </visual>
    <collision>
      <geometry>
        <sphere radius="0.025"/>
      </geometry>
      <origin rpy="0 0 0" xyz="0 0 --0.0025"/>
    </collision>
    <inertial>
      <mass value="0.2"/>
      <inertia ixx="0.2" ixy="0.2" ixz="0.2" iyy="0.2" iyz="0.2" izz="0.2"/>
    </inertial>
  </link>
  <!-- femur link definition -->
  <link name="right_front_femur">
    <visual>
      <geometry>
        <cylinder length="0.15" radius="0.025"/>
      </geometry>
      <origin rpy="0 0 0" xyz="0 0 -0.075"/>
    </visual>
    <collision>
      <geometry>
        <sphere radius="0.025"/>
      </geometry>
      <origin rpy="0 0 0" xyz="0 0 -0.1375"/>
    </collision>
    <inertial>
      <mass value="0.2"/>
      <inertia ixx="0.2" ixy="0.2" ixz="0.2" iyy="0.2" iyz="0.2" izz="0.2"/>
    </inertial>
  </link>
  <!-- tibia link definition -->
  <link name="right_front_tibia">
    <visual>
      <geometry>
        <cylinder length="0.15" radius="0.025"/>
      </geometry>
      <origin rpy="0 0 0" xyz="0 0 -0.075"/>
    </visual>
    <collision>
      <geometry>
        <sphere radius="0.025"/>
      </geometry>
      <origin rpy="0 0 0" xyz="0 0 -0.1375"/>
    </collision>
    <inertial>
      <mass value="0.2"/>
      <inertia ixx="0.2" ixy="0.2" ixz="0.2" iyy="0.2" iyz="0.2" izz="0.2"/>
    </inertial>
  </link>
  <!-- joint 1 definition -->
  <joint name="right_front_coax_joint" type="revolute">
    <parent link="base_link"/>
    <child link="right_front_coax"/>
    <axis xyz="0 -1 0"/>
    <limit effort="0.2" lower="-0.785398163397" upper="0.785398163397" velocity="0.2"/>
    <origin rpy="-1.57079632679 0 0" xyz="0.15 -0.075 0"/>
  </joint>
  <!-- joint 2 definition -->
  <joint name="right_front_femur_joint" type="revolute">
    <parent link="right_front_coax"/>
    <child link="right_front_femur"/>
    <axis xyz="-1 0 0"/>
    <limit effort="0.2" lower="-0.785398163397" upper="0.785398163397" velocity="0.2"/>
    <origin rpy="0 0 0" xyz="0 0 -0.01"/>
  </joint>
  <!-- joint 3 definition -->
  <joint name="right_front_tibia_joint" type="revolute">
    <parent link="right_front_femur"/>
    <child link="right_front_tibia"/>
    <axis xyz="-1 0 0"/>
    <limit effort="0.2" lower="-2.35619449019" upper="0.0" velocity="0.2"/>
    <origin rpy="0 0 0" xyz="0 0 -0.15"/>
  </joint>
  <!-- coax link definition -->
  <link name="right_central_coax">
    <visual>
      <geometry>
        <cylinder length="0.01" radius="0.025"/>
      </geometry>
      <origin rpy="0 0 1.57079632679" xyz="0 0 -0.005"/>
    </visual>
    <collision>
      <geometry>
        <sphere radius="0.025"/>
      </geometry>
      <origin rpy="0 0 0" xyz="0 0 --0.0025"/>
    </collision>
    <inertial>
      <mass value="0.2"/>
      <inertia ixx="0.2" ixy="0.2" ixz="0.2" iyy="0.2" iyz="0.2" izz="0.2"/>
    </inertial>
  </link>
  <!-- femur link definition -->
  <link name="right_central_femur">
    <visual>
      <geometry>
        <cylinder length="0.15" radius="0.025"/>
      </geometry>
      <origin rpy="0 0 0" xyz="0 0 -0.075"/>
    </visual>
    <collision>
      <geometry>
        <sphere radius="0.025"/>
      </geometry>
      <origin rpy="0 0 0" xyz="0 0 -0.1375"/>
    </collision>
    <inertial>
      <mass value="0.2"/>
      <inertia ixx="0.2" ixy="0.2" ixz="0.2" iyy="0.2" iyz="0.2" izz="0.2"/>
    </inertial>
  </link>
  <!-- tibia link definition -->
  <link name="right_central_tibia">
    <visual>
      <geometry>
        <cylinder length="0.15" radius="0.025"/>
      </geometry>
      <origin rpy="0 0 0" xyz="0 0 -0.075"/>
    </visual>
    <collision>
      <geometry>
        <sphere radius="0.025"/>
      </geometry>
      <origin rpy="0 0 0" xyz="0 0 -0.1375"/>
    </collision>
    <inertial>
      <mass value="0.2"/>
      <inertia ixx="0.2" ixy="0.2" ixz="0.2" iyy="0.2" iyz="0.2" izz="0.2"/>
    </inertial>
  </link>
  <!-- joint 1 definition -->
  <joint name="right_central_coax_joint" type="revolute">
    <parent link="base_link"/>
    <child link="right_central_coax"/>
    <axis xyz="0 -1 0"/>
    <limit effort="0.2" lower="-0.785398163397" upper="0.785398163397" velocity="0.2"/>
    <origin rpy="-1.57079632679 0 0" xyz="0 -0.075 0"/>
  </joint>
  <!-- joint 2 definition -->
  <joint name="right_central_femur_joint" type="revolute">
    <parent link="right_central_coax"/>
    <child link="right_central_femur"/>
    <axis xyz="-1 0 0"/>
    <limit effort="0.2" lower="-0.785398163397" upper="0.785398163397" velocity="0.2"/>
    <origin rpy="0 0 0" xyz="0 0 -0.01"/>
  </joint>
  <!-- joint 3 definition -->
  <joint name="right_central_tibia_joint" type="revolute">
    <parent link="right_central_femur"/>
    <child link="right_central_tibia"/>
    <axis xyz="-1 0 0"/>
    <limit effort="0.2" lower="-2.35619449019" upper="0.0" velocity="0.2"/>
    <origin rpy="0 0 0" xyz="0 0 -0.15"/>
  </joint>
  <!-- coax link definition -->
  <link name="right_rear_coax">
    <visual>
      <geometry>
        <cylinder length="0.01" radius="0.025"/>
      </geometry>
      <origin rpy="0 0 1.57079632679" xyz="0 0 -0.005"/>
    </visual>
    <collision>
      <geometry>
        <sphere radius="0.025"/>
      </geometry>
      <origin rpy="0 0 0" xyz="0 0 --0.0025"/>
    </collision>
    <inertial>
      <mass value="0.2"/>
      <inertia ixx="0.2" ixy="0.2" ixz="0.2" iyy="0.2" iyz="0.2" izz="0.2"/>
    </inertial>
  </link>
  <!-- femur link definition -->
  <link name="right_rear_femur">
    <visual>
      <geometry>
        <cylinder length="0.15" radius="0.025"/>
      </geometry>
      <origin rpy="0 0 0" xyz="0 0 -0.075"/>
    </visual>
    <collision>
      <geometry>
        <sphere radius="0.025"/>
      </geometry>
      <origin rpy="0 0 0" xyz="0 0 -0.1375"/>
    </collision>
    <inertial>
      <mass value="0.2"/>
      <inertia ixx="0.2" ixy="0.2" ixz="0.2" iyy="0.2" iyz="0.2" izz="0.2"/>
    </inertial>
  </link>
  <!-- tibia link definition -->
  <link name="right_rear_tibia">
    <visual>
      <geometry>
        <cylinder length="0.15" radius="0.025"/>
      </geometry>
      <origin rpy="0 0 0" xyz="0 0 -0.075"/>
    </visual>
    <collision>
      <geometry>
        <sphere radius="0.025"/>
      </geometry>
      <origin rpy="0 0 0" xyz="0 0 -0.1375"/>
    </collision>
    <inertial>
      <mass value="0.2"/>
      <inertia ixx="0.2" ixy="0.2" ixz="0.2" iyy="0.2" iyz="0.2" izz="0.2"/>
    </inertial>
  </link>
  <!-- joint 1 definition -->
  <joint name="right_rear_coax_joint" type="revolute">
    <parent link="base_link"/>
    <child link="right_rear_coax"/>
    <axis xyz="0 -1 0"/>
    <limit effort="0.2" lower="-0.785398163397" upper="0.785398163397" velocity="0.2"/>
    <origin rpy="-1.57079632679 0 0" xyz="-0.15 -0.075 0"/>
  </joint>
  <!-- joint 2 definition -->
  <joint name="right_rear_femur_joint" type="revolute">
    <parent link="right_rear_coax"/>
    <child link="right_rear_femur"/>
    <axis xyz="-1 0 0"/>
    <limit effort="0.2" lower="-0.785398163397" upper="0.785398163397" velocity="0.2"/>
    <origin rpy="0 0 0" xyz="0 0 -0.01"/>
  </joint>
  <!-- joint 3 definition -->
  <joint name="right_rear_tibia_joint" type="revolute">
    <parent link="right_rear_femur"/>
    <child link="right_rear_tibia"/>
    <axis xyz="-1 0 0"/>
    <limit effort="0.2" lower="-2.35619449019" upper="0.0" velocity="0.2"/>
    <origin rpy="0 0 0" xyz="0 0 -0.15"/>
  </joint>
</robot>

