<?xml version="1.0" encoding="utf-8"?>
<!-- =================================================================================== -->
<!-- |    This document was autogenerated by xacro from hexapod.urdf.xacro             | -->
<!-- |    EDITING THIS FILE BY HAND IS NOT RECOMMENDED                                 | -->
<!-- =================================================================================== -->
<robot name="hexapod">
  <link name="base_link"/>
  <link name="body">
    <visual>
      <geometry>
        <mesh filename="package://the_walking_thread_gazebo/src/urdf/meshes/the_walking_thread/frame.stl" scale="1 1 1"/>
      </geometry>
      <origin xyz="0 0 0"/>
    </visual>
    <collision>
      <geometry>
        <box size="0.3618                      0.117                      0.0525"/>
      </geometry>
    </collision>
    <inertial>
      <mass value="0.209677"/>
      <inertia ixx="0.00022432" ixy="0.0" ixz="0.0" iyy="0.0041164" iyz="0.0" izz="0.00422412"/>
    </inertial>
  </link>
  <joint name="base_link_to_body_joint" type="fixed">
    <origin rpy="0 0 0" xyz="0 0 0"/>
    <parent link="base_link"/>
    <child link="body"/>
  </joint>
  <link name="left_front_coxa">
    <visual>
      <geometry>
        <mesh filename="package://the_walking_thread_gazebo/src/urdf/meshes/the_walking_thread/coxa.stl" scale="1 1 1"/>
      </geometry>
      <origin rpy="1.57079632679 0 0" xyz="0 0 -0.01825"/>
    </visual>
    <collision>
      <geometry>
        <sphere radius="0.019"/>
      </geometry>
      <origin rpy="0 0 0" xyz="0 0 -0.0175"/>
    </collision>
    <inertial>
      <mass value="0.12131"/>
      <inertia ixx="9.165e-05" ixy="5.98e-06" ixz="-1.8e-06" iyy="3.309e-05" iyz="-1.473e-05" izz="8.256e-05"/>
    </inertial>
  </link>
  <link name="left_front_femur">
    <visual>
      <geometry>
        <mesh filename="package://the_walking_thread_gazebo/src/urdf/meshes/the_walking_thread/femur.stl" scale="1 1 1"/>
      </geometry>
      <origin rpy="1.57079632679 0 0" xyz="0 0 -0.0285"/>
    </visual>
    <collision>
      <geometry>
        <sphere radius="0.03"/>
      </geometry>
      <origin rpy="0 0 0" xyz="0 0 -0.027"/>
    </collision>
    <inertial>
      <mass value="0.02748837"/>
      <inertia ixx="1.094e-05" ixy="0.0" ixz="0.0" iyy="1.457e-05" iyz="0.0" izz="2.278e-05"/>
    </inertial>
  </link>
  <link name="left_front_tibia">
    <visual>
      <geometry>
        <mesh filename="package://the_walking_thread_gazebo/src/urdf/meshes/the_walking_thread/tibia.stl" scale="1 1 1"/>
      </geometry>
      <origin rpy="1.57079632679 0 0" xyz="0 0 -0.0815"/>
    </visual>
    <collision>
      <geometry>
        <sphere radius="0.0065"/>
      </geometry>
      <origin rpy="0 0 0" xyz="0 0 -0.1565"/>
    </collision>
    <inertial>
      <mass value="0.08475"/>
      <inertia ixx="0.0001634" ixy="-3.17e-06" ixz="-2.9e-07" iyy="1.251e-05" iyz="3.18e-06" izz="0.00016808"/>
    </inertial>
  </link>
  <joint name="left_front_body_to_coxa_joint" type="revolute">
    <parent link="body"/>
    <origin rpy="-1.57079632679 0 3.14159265359" xyz="0.1809                        0.0585                        0"/>
    <child link="left_front_coxa"/>
    <axis xyz="0 1 0"/>
    <limit effort="0.5295591" lower="-0.785398163397" upper="0.785398163397" velocity="0.003141593"/>
  </joint>
  <!-- TRANSMITION DEFINITION -->
  <transmission name="left_front_body_to_coxa_transmition">
    <type>transmission_interface/SimpleTransmission</type>
    <joint name="left_front_body_to_coxa_joint">
      <hardwareInterface>hardware_interface/EffortJointInterface</hardwareInterface>
    </joint>
    <actuator name="left_front_body_to_coxa_actuator">
      <hardwareInterface>hardware_interface/EffortJointInterface</hardwareInterface>
      <mechanicalReduction>1</mechanicalReduction>
    </actuator>
  </transmission>
  <joint name="left_front_coxa_to_femur_joint" type="revolute">
    <parent link="left_front_coxa"/>
    <origin rpy="0 0 0" xyz="0 -0.019 -0.0365"/>
    <child link="left_front_femur"/>
    <axis xyz="1 0 0"/>
    <limit effort="0.5295591" lower="-0.785398163397" upper="0.785398163397" velocity="0.003141593"/>
  </joint>
  <!-- TRANSMITION DEFINITION -->
  <transmission name="left_front_coxa_to_femur_transmition">
    <type>transmission_interface/SimpleTransmission</type>
    <joint name="left_front_coxa_to_femur_joint">
      <hardwareInterface>hardware_interface/EffortJointInterface</hardwareInterface>
    </joint>
    <actuator name="left_front_coxa_to_femur_actuator">
      <hardwareInterface>hardware_interface/EffortJointInterface</hardwareInterface>
      <mechanicalReduction>1</mechanicalReduction>
    </actuator>
  </transmission>
  <joint name="left_front_femur_to_tibia_joint" type="revolute">
    <parent link="left_front_femur"/>
    <origin rpy="0 0 0" xyz="0 0 -0.057"/>
    <child link="left_front_tibia"/>
    <axis xyz="1 0 0"/>
    <limit effort="0.5295591" lower="0.0" upper="2.35619449019" velocity="0.003141593"/>
  </joint>
  <!-- TRANSMITION DEFINITION -->
  <transmission name="left_front_femur_to_tibia_transmition">
    <type>transmission_interface/SimpleTransmission</type>
    <joint name="left_front_femur_to_tibia_joint">
      <hardwareInterface>hardware_interface/EffortJointInterface</hardwareInterface>
    </joint>
    <actuator name="left_front_femur_to_tibia_actuator">
      <hardwareInterface>hardware_interface/EffortJointInterface</hardwareInterface>
      <mechanicalReduction>1</mechanicalReduction>
    </actuator>
  </transmission>
  <gazebo reference="left_front_coxa">
    <mu1>0.9</mu1>
    <mu2>0.6</mu2>
  </gazebo>
  <link name="left_central_coxa">
    <visual>
      <geometry>
        <mesh filename="package://the_walking_thread_gazebo/src/urdf/meshes/the_walking_thread/coxa.stl" scale="1 1 1"/>
      </geometry>
      <origin rpy="1.57079632679 0 0" xyz="0 0 -0.01825"/>
    </visual>
    <collision>
      <geometry>
        <sphere radius="0.019"/>
      </geometry>
      <origin rpy="0 0 0" xyz="0 0 -0.0175"/>
    </collision>
    <inertial>
      <mass value="0.12131"/>
      <inertia ixx="9.165e-05" ixy="5.98e-06" ixz="-1.8e-06" iyy="3.309e-05" iyz="-1.473e-05" izz="8.256e-05"/>
    </inertial>
  </link>
  <link name="left_central_femur">
    <visual>
      <geometry>
        <mesh filename="package://the_walking_thread_gazebo/src/urdf/meshes/the_walking_thread/femur.stl" scale="1 1 1"/>
      </geometry>
      <origin rpy="1.57079632679 0 0" xyz="0 0 -0.0285"/>
    </visual>
    <collision>
      <geometry>
        <sphere radius="0.03"/>
      </geometry>
      <origin rpy="0 0 0" xyz="0 0 -0.027"/>
    </collision>
    <inertial>
      <mass value="0.02748837"/>
      <inertia ixx="1.094e-05" ixy="0.0" ixz="0.0" iyy="1.457e-05" iyz="0.0" izz="2.278e-05"/>
    </inertial>
  </link>
  <link name="left_central_tibia">
    <visual>
      <geometry>
        <mesh filename="package://the_walking_thread_gazebo/src/urdf/meshes/the_walking_thread/tibia.stl" scale="1 1 1"/>
      </geometry>
      <origin rpy="1.57079632679 0 0" xyz="0 0 -0.0815"/>
    </visual>
    <collision>
      <geometry>
        <sphere radius="0.0065"/>
      </geometry>
      <origin rpy="0 0 0" xyz="0 0 -0.1565"/>
    </collision>
    <inertial>
      <mass value="0.08475"/>
      <inertia ixx="0.0001634" ixy="-3.17e-06" ixz="-2.9e-07" iyy="1.251e-05" iyz="3.18e-06" izz="0.00016808"/>
    </inertial>
  </link>
  <joint name="left_central_body_to_coxa_joint" type="revolute">
    <parent link="body"/>
    <origin rpy="-1.57079632679 0 3.14159265359" xyz="0                        0.0585                        0"/>
    <child link="left_central_coxa"/>
    <axis xyz="0 1 0"/>
    <limit effort="0.5295591" lower="-0.785398163397" upper="0.785398163397" velocity="0.003141593"/>
  </joint>
  <!-- TRANSMITION DEFINITION -->
  <transmission name="left_central_body_to_coxa_transmition">
    <type>transmission_interface/SimpleTransmission</type>
    <joint name="left_central_body_to_coxa_joint">
      <hardwareInterface>hardware_interface/EffortJointInterface</hardwareInterface>
    </joint>
    <actuator name="left_central_body_to_coxa_actuator">
      <hardwareInterface>hardware_interface/EffortJointInterface</hardwareInterface>
      <mechanicalReduction>1</mechanicalReduction>
    </actuator>
  </transmission>
  <joint name="left_central_coxa_to_femur_joint" type="revolute">
    <parent link="left_central_coxa"/>
    <origin rpy="0 0 0" xyz="0 -0.019 -0.0365"/>
    <child link="left_central_femur"/>
    <axis xyz="1 0 0"/>
    <limit effort="0.5295591" lower="-0.785398163397" upper="0.785398163397" velocity="0.003141593"/>
  </joint>
  <!-- TRANSMITION DEFINITION -->
  <transmission name="left_central_coxa_to_femur_transmition">
    <type>transmission_interface/SimpleTransmission</type>
    <joint name="left_central_coxa_to_femur_joint">
      <hardwareInterface>hardware_interface/EffortJointInterface</hardwareInterface>
    </joint>
    <actuator name="left_central_coxa_to_femur_actuator">
      <hardwareInterface>hardware_interface/EffortJointInterface</hardwareInterface>
      <mechanicalReduction>1</mechanicalReduction>
    </actuator>
  </transmission>
  <joint name="left_central_femur_to_tibia_joint" type="revolute">
    <parent link="left_central_femur"/>
    <origin rpy="0 0 0" xyz="0 0 -0.057"/>
    <child link="left_central_tibia"/>
    <axis xyz="1 0 0"/>
    <limit effort="0.5295591" lower="0.0" upper="2.35619449019" velocity="0.003141593"/>
  </joint>
  <!-- TRANSMITION DEFINITION -->
  <transmission name="left_central_femur_to_tibia_transmition">
    <type>transmission_interface/SimpleTransmission</type>
    <joint name="left_central_femur_to_tibia_joint">
      <hardwareInterface>hardware_interface/EffortJointInterface</hardwareInterface>
    </joint>
    <actuator name="left_central_femur_to_tibia_actuator">
      <hardwareInterface>hardware_interface/EffortJointInterface</hardwareInterface>
      <mechanicalReduction>1</mechanicalReduction>
    </actuator>
  </transmission>
  <gazebo reference="left_central_coxa">
    <mu1>0.9</mu1>
    <mu2>0.6</mu2>
  </gazebo>
  <link name="left_rear_coxa">
    <visual>
      <geometry>
        <mesh filename="package://the_walking_thread_gazebo/src/urdf/meshes/the_walking_thread/coxa.stl" scale="1 1 1"/>
      </geometry>
      <origin rpy="1.57079632679 0 0" xyz="0 0 -0.01825"/>
    </visual>
    <collision>
      <geometry>
        <sphere radius="0.019"/>
      </geometry>
      <origin rpy="0 0 0" xyz="0 0 -0.0175"/>
    </collision>
    <inertial>
      <mass value="0.12131"/>
      <inertia ixx="9.165e-05" ixy="5.98e-06" ixz="-1.8e-06" iyy="3.309e-05" iyz="-1.473e-05" izz="8.256e-05"/>
    </inertial>
  </link>
  <link name="left_rear_femur">
    <visual>
      <geometry>
        <mesh filename="package://the_walking_thread_gazebo/src/urdf/meshes/the_walking_thread/femur.stl" scale="1 1 1"/>
      </geometry>
      <origin rpy="1.57079632679 0 0" xyz="0 0 -0.0285"/>
    </visual>
    <collision>
      <geometry>
        <sphere radius="0.03"/>
      </geometry>
      <origin rpy="0 0 0" xyz="0 0 -0.027"/>
    </collision>
    <inertial>
      <mass value="0.02748837"/>
      <inertia ixx="1.094e-05" ixy="0.0" ixz="0.0" iyy="1.457e-05" iyz="0.0" izz="2.278e-05"/>
    </inertial>
  </link>
  <link name="left_rear_tibia">
    <visual>
      <geometry>
        <mesh filename="package://the_walking_thread_gazebo/src/urdf/meshes/the_walking_thread/tibia.stl" scale="1 1 1"/>
      </geometry>
      <origin rpy="1.57079632679 0 0" xyz="0 0 -0.0815"/>
    </visual>
    <collision>
      <geometry>
        <sphere radius="0.0065"/>
      </geometry>
      <origin rpy="0 0 0" xyz="0 0 -0.1565"/>
    </collision>
    <inertial>
      <mass value="0.08475"/>
      <inertia ixx="0.0001634" ixy="-3.17e-06" ixz="-2.9e-07" iyy="1.251e-05" iyz="3.18e-06" izz="0.00016808"/>
    </inertial>
  </link>
  <joint name="left_rear_body_to_coxa_joint" type="revolute">
    <parent link="body"/>
    <origin rpy="-1.57079632679 0 3.14159265359" xyz="-0.1809                        0.0585                        0"/>
    <child link="left_rear_coxa"/>
    <axis xyz="0 1 0"/>
    <limit effort="0.5295591" lower="-0.785398163397" upper="0.785398163397" velocity="0.003141593"/>
  </joint>
  <!-- TRANSMITION DEFINITION -->
  <transmission name="left_rear_body_to_coxa_transmition">
    <type>transmission_interface/SimpleTransmission</type>
    <joint name="left_rear_body_to_coxa_joint">
      <hardwareInterface>hardware_interface/EffortJointInterface</hardwareInterface>
    </joint>
    <actuator name="left_rear_body_to_coxa_actuator">
      <hardwareInterface>hardware_interface/EffortJointInterface</hardwareInterface>
      <mechanicalReduction>1</mechanicalReduction>
    </actuator>
  </transmission>
  <joint name="left_rear_coxa_to_femur_joint" type="revolute">
    <parent link="left_rear_coxa"/>
    <origin rpy="0 0 0" xyz="0 -0.019 -0.0365"/>
    <child link="left_rear_femur"/>
    <axis xyz="1 0 0"/>
    <limit effort="0.5295591" lower="-0.785398163397" upper="0.785398163397" velocity="0.003141593"/>
  </joint>
  <!-- TRANSMITION DEFINITION -->
  <transmission name="left_rear_coxa_to_femur_transmition">
    <type>transmission_interface/SimpleTransmission</type>
    <joint name="left_rear_coxa_to_femur_joint">
      <hardwareInterface>hardware_interface/EffortJointInterface</hardwareInterface>
    </joint>
    <actuator name="left_rear_coxa_to_femur_actuator">
      <hardwareInterface>hardware_interface/EffortJointInterface</hardwareInterface>
      <mechanicalReduction>1</mechanicalReduction>
    </actuator>
  </transmission>
  <joint name="left_rear_femur_to_tibia_joint" type="revolute">
    <parent link="left_rear_femur"/>
    <origin rpy="0 0 0" xyz="0 0 -0.057"/>
    <child link="left_rear_tibia"/>
    <axis xyz="1 0 0"/>
    <limit effort="0.5295591" lower="0.0" upper="2.35619449019" velocity="0.003141593"/>
  </joint>
  <!-- TRANSMITION DEFINITION -->
  <transmission name="left_rear_femur_to_tibia_transmition">
    <type>transmission_interface/SimpleTransmission</type>
    <joint name="left_rear_femur_to_tibia_joint">
      <hardwareInterface>hardware_interface/EffortJointInterface</hardwareInterface>
    </joint>
    <actuator name="left_rear_femur_to_tibia_actuator">
      <hardwareInterface>hardware_interface/EffortJointInterface</hardwareInterface>
      <mechanicalReduction>1</mechanicalReduction>
    </actuator>
  </transmission>
  <gazebo reference="left_rear_coxa">
    <mu1>0.9</mu1>
    <mu2>0.6</mu2>
  </gazebo>
  <link name="right_front_coxa">
    <visual>
      <geometry>
        <mesh filename="package://the_walking_thread_gazebo/src/urdf/meshes/the_walking_thread/coxa.stl" scale="1 1 1"/>
      </geometry>
      <origin rpy="1.57079632679 0 0" xyz="0 0 -0.01825"/>
    </visual>
    <collision>
      <geometry>
        <sphere radius="0.019"/>
      </geometry>
      <origin rpy="0 0 0" xyz="0 0 -0.0175"/>
    </collision>
    <inertial>
      <mass value="0.12131"/>
      <inertia ixx="9.165e-05" ixy="5.98e-06" ixz="-1.8e-06" iyy="3.309e-05" iyz="-1.473e-05" izz="8.256e-05"/>
    </inertial>
  </link>
  <link name="right_front_femur">
    <visual>
      <geometry>
        <mesh filename="package://the_walking_thread_gazebo/src/urdf/meshes/the_walking_thread/femur.stl" scale="1 1 1"/>
      </geometry>
      <origin rpy="1.57079632679 0 0" xyz="0 0 -0.0285"/>
    </visual>
    <collision>
      <geometry>
        <sphere radius="0.03"/>
      </geometry>
      <origin rpy="0 0 0" xyz="0 0 -0.027"/>
    </collision>
    <inertial>
      <mass value="0.02748837"/>
      <inertia ixx="1.094e-05" ixy="0.0" ixz="0.0" iyy="1.457e-05" iyz="0.0" izz="2.278e-05"/>
    </inertial>
  </link>
  <link name="right_front_tibia">
    <visual>
      <geometry>
        <mesh filename="package://the_walking_thread_gazebo/src/urdf/meshes/the_walking_thread/tibia.stl" scale="1 1 1"/>
      </geometry>
      <origin rpy="1.57079632679 0 0" xyz="0 0 -0.0815"/>
    </visual>
    <collision>
      <geometry>
        <sphere radius="0.0065"/>
      </geometry>
      <origin rpy="0 0 0" xyz="0 0 -0.1565"/>
    </collision>
    <inertial>
      <mass value="0.08475"/>
      <inertia ixx="0.0001634" ixy="-3.17e-06" ixz="-2.9e-07" iyy="1.251e-05" iyz="3.18e-06" izz="0.00016808"/>
    </inertial>
  </link>
  <joint name="right_front_body_to_coxa_joint" type="revolute">
    <parent link="body"/>
    <origin rpy="-1.57079632679 0 0.0" xyz="0.1809                        -0.0585                        0"/>
    <child link="right_front_coxa"/>
    <axis xyz="0 -1 0"/>
    <limit effort="0.5295591" lower="-0.785398163397" upper="0.785398163397" velocity="0.003141593"/>
  </joint>
  <!-- TRANSMITION DEFINITION -->
  <transmission name="right_front_body_to_coxa_transmition">
    <type>transmission_interface/SimpleTransmission</type>
    <joint name="right_front_body_to_coxa_joint">
      <hardwareInterface>hardware_interface/EffortJointInterface</hardwareInterface>
    </joint>
    <actuator name="right_front_body_to_coxa_actuator">
      <hardwareInterface>hardware_interface/EffortJointInterface</hardwareInterface>
      <mechanicalReduction>1</mechanicalReduction>
    </actuator>
  </transmission>
  <joint name="right_front_coxa_to_femur_joint" type="revolute">
    <parent link="right_front_coxa"/>
    <origin rpy="0 0 0" xyz="0 -0.019 -0.0365"/>
    <child link="right_front_femur"/>
    <axis xyz="1 0 0"/>
    <limit effort="0.5295591" lower="-0.785398163397" upper="0.785398163397" velocity="0.003141593"/>
  </joint>
  <!-- TRANSMITION DEFINITION -->
  <transmission name="right_front_coxa_to_femur_transmition">
    <type>transmission_interface/SimpleTransmission</type>
    <joint name="right_front_coxa_to_femur_joint">
      <hardwareInterface>hardware_interface/EffortJointInterface</hardwareInterface>
    </joint>
    <actuator name="right_front_coxa_to_femur_actuator">
      <hardwareInterface>hardware_interface/EffortJointInterface</hardwareInterface>
      <mechanicalReduction>1</mechanicalReduction>
    </actuator>
  </transmission>
  <joint name="right_front_femur_to_tibia_joint" type="revolute">
    <parent link="right_front_femur"/>
    <origin rpy="0 0 0" xyz="0 0 -0.057"/>
    <child link="right_front_tibia"/>
    <axis xyz="1 0 0"/>
    <limit effort="0.5295591" lower="0.0" upper="2.35619449019" velocity="0.003141593"/>
  </joint>
  <!-- TRANSMITION DEFINITION -->
  <transmission name="right_front_femur_to_tibia_transmition">
    <type>transmission_interface/SimpleTransmission</type>
    <joint name="right_front_femur_to_tibia_joint">
      <hardwareInterface>hardware_interface/EffortJointInterface</hardwareInterface>
    </joint>
    <actuator name="right_front_femur_to_tibia_actuator">
      <hardwareInterface>hardware_interface/EffortJointInterface</hardwareInterface>
      <mechanicalReduction>1</mechanicalReduction>
    </actuator>
  </transmission>
  <gazebo reference="right_front_coxa">
    <mu1>0.9</mu1>
    <mu2>0.6</mu2>
  </gazebo>
  <link name="right_central_coxa">
    <visual>
      <geometry>
        <mesh filename="package://the_walking_thread_gazebo/src/urdf/meshes/the_walking_thread/coxa.stl" scale="1 1 1"/>
      </geometry>
      <origin rpy="1.57079632679 0 0" xyz="0 0 -0.01825"/>
    </visual>
    <collision>
      <geometry>
        <sphere radius="0.019"/>
      </geometry>
      <origin rpy="0 0 0" xyz="0 0 -0.0175"/>
    </collision>
    <inertial>
      <mass value="0.12131"/>
      <inertia ixx="9.165e-05" ixy="5.98e-06" ixz="-1.8e-06" iyy="3.309e-05" iyz="-1.473e-05" izz="8.256e-05"/>
    </inertial>
  </link>
  <link name="right_central_femur">
    <visual>
      <geometry>
        <mesh filename="package://the_walking_thread_gazebo/src/urdf/meshes/the_walking_thread/femur.stl" scale="1 1 1"/>
      </geometry>
      <origin rpy="1.57079632679 0 0" xyz="0 0 -0.0285"/>
    </visual>
    <collision>
      <geometry>
        <sphere radius="0.03"/>
      </geometry>
      <origin rpy="0 0 0" xyz="0 0 -0.027"/>
    </collision>
    <inertial>
      <mass value="0.02748837"/>
      <inertia ixx="1.094e-05" ixy="0.0" ixz="0.0" iyy="1.457e-05" iyz="0.0" izz="2.278e-05"/>
    </inertial>
  </link>
  <link name="right_central_tibia">
    <visual>
      <geometry>
        <mesh filename="package://the_walking_thread_gazebo/src/urdf/meshes/the_walking_thread/tibia.stl" scale="1 1 1"/>
      </geometry>
      <origin rpy="1.57079632679 0 0" xyz="0 0 -0.0815"/>
    </visual>
    <collision>
      <geometry>
        <sphere radius="0.0065"/>
      </geometry>
      <origin rpy="0 0 0" xyz="0 0 -0.1565"/>
    </collision>
    <inertial>
      <mass value="0.08475"/>
      <inertia ixx="0.0001634" ixy="-3.17e-06" ixz="-2.9e-07" iyy="1.251e-05" iyz="3.18e-06" izz="0.00016808"/>
    </inertial>
  </link>
  <joint name="right_central_body_to_coxa_joint" type="revolute">
    <parent link="body"/>
    <origin rpy="-1.57079632679 0 0.0" xyz="0                        -0.0585                        0"/>
    <child link="right_central_coxa"/>
    <axis xyz="0 -1 0"/>
    <limit effort="0.5295591" lower="-0.785398163397" upper="0.785398163397" velocity="0.003141593"/>
  </joint>
  <!-- TRANSMITION DEFINITION -->
  <transmission name="right_central_body_to_coxa_transmition">
    <type>transmission_interface/SimpleTransmission</type>
    <joint name="right_central_body_to_coxa_joint">
      <hardwareInterface>hardware_interface/EffortJointInterface</hardwareInterface>
    </joint>
    <actuator name="right_central_body_to_coxa_actuator">
      <hardwareInterface>hardware_interface/EffortJointInterface</hardwareInterface>
      <mechanicalReduction>1</mechanicalReduction>
    </actuator>
  </transmission>
  <joint name="right_central_coxa_to_femur_joint" type="revolute">
    <parent link="right_central_coxa"/>
    <origin rpy="0 0 0" xyz="0 -0.019 -0.0365"/>
    <child link="right_central_femur"/>
    <axis xyz="1 0 0"/>
    <limit effort="0.5295591" lower="-0.785398163397" upper="0.785398163397" velocity="0.003141593"/>
  </joint>
  <!-- TRANSMITION DEFINITION -->
  <transmission name="right_central_coxa_to_femur_transmition">
    <type>transmission_interface/SimpleTransmission</type>
    <joint name="right_central_coxa_to_femur_joint">
      <hardwareInterface>hardware_interface/EffortJointInterface</hardwareInterface>
    </joint>
    <actuator name="right_central_coxa_to_femur_actuator">
      <hardwareInterface>hardware_interface/EffortJointInterface</hardwareInterface>
      <mechanicalReduction>1</mechanicalReduction>
    </actuator>
  </transmission>
  <joint name="right_central_femur_to_tibia_joint" type="revolute">
    <parent link="right_central_femur"/>
    <origin rpy="0 0 0" xyz="0 0 -0.057"/>
    <child link="right_central_tibia"/>
    <axis xyz="1 0 0"/>
    <limit effort="0.5295591" lower="0.0" upper="2.35619449019" velocity="0.003141593"/>
  </joint>
  <!-- TRANSMITION DEFINITION -->
  <transmission name="right_central_femur_to_tibia_transmition">
    <type>transmission_interface/SimpleTransmission</type>
    <joint name="right_central_femur_to_tibia_joint">
      <hardwareInterface>hardware_interface/EffortJointInterface</hardwareInterface>
    </joint>
    <actuator name="right_central_femur_to_tibia_actuator">
      <hardwareInterface>hardware_interface/EffortJointInterface</hardwareInterface>
      <mechanicalReduction>1</mechanicalReduction>
    </actuator>
  </transmission>
  <gazebo reference="right_central_coxa">
    <mu1>0.9</mu1>
    <mu2>0.6</mu2>
  </gazebo>
  <link name="right_rear_coxa">
    <visual>
      <geometry>
        <mesh filename="package://the_walking_thread_gazebo/src/urdf/meshes/the_walking_thread/coxa.stl" scale="1 1 1"/>
      </geometry>
      <origin rpy="1.57079632679 0 0" xyz="0 0 -0.01825"/>
    </visual>
    <collision>
      <geometry>
        <sphere radius="0.019"/>
      </geometry>
      <origin rpy="0 0 0" xyz="0 0 -0.0175"/>
    </collision>
    <inertial>
      <mass value="0.12131"/>
      <inertia ixx="9.165e-05" ixy="5.98e-06" ixz="-1.8e-06" iyy="3.309e-05" iyz="-1.473e-05" izz="8.256e-05"/>
    </inertial>
  </link>
  <link name="right_rear_femur">
    <visual>
      <geometry>
        <mesh filename="package://the_walking_thread_gazebo/src/urdf/meshes/the_walking_thread/femur.stl" scale="1 1 1"/>
      </geometry>
      <origin rpy="1.57079632679 0 0" xyz="0 0 -0.0285"/>
    </visual>
    <collision>
      <geometry>
        <sphere radius="0.03"/>
      </geometry>
      <origin rpy="0 0 0" xyz="0 0 -0.027"/>
    </collision>
    <inertial>
      <mass value="0.02748837"/>
      <inertia ixx="1.094e-05" ixy="0.0" ixz="0.0" iyy="1.457e-05" iyz="0.0" izz="2.278e-05"/>
    </inertial>
  </link>
  <link name="right_rear_tibia">
    <visual>
      <geometry>
        <mesh filename="package://the_walking_thread_gazebo/src/urdf/meshes/the_walking_thread/tibia.stl" scale="1 1 1"/>
      </geometry>
      <origin rpy="1.57079632679 0 0" xyz="0 0 -0.0815"/>
    </visual>
    <collision>
      <geometry>
        <sphere radius="0.0065"/>
      </geometry>
      <origin rpy="0 0 0" xyz="0 0 -0.1565"/>
    </collision>
    <inertial>
      <mass value="0.08475"/>
      <inertia ixx="0.0001634" ixy="-3.17e-06" ixz="-2.9e-07" iyy="1.251e-05" iyz="3.18e-06" izz="0.00016808"/>
    </inertial>
  </link>
  <joint name="right_rear_body_to_coxa_joint" type="revolute">
    <parent link="body"/>
    <origin rpy="-1.57079632679 0 0.0" xyz="-0.1809                        -0.0585                        0"/>
    <child link="right_rear_coxa"/>
    <axis xyz="0 -1 0"/>
    <limit effort="0.5295591" lower="-0.785398163397" upper="0.785398163397" velocity="0.003141593"/>
  </joint>
  <!-- TRANSMITION DEFINITION -->
  <transmission name="right_rear_body_to_coxa_transmition">
    <type>transmission_interface/SimpleTransmission</type>
    <joint name="right_rear_body_to_coxa_joint">
      <hardwareInterface>hardware_interface/EffortJointInterface</hardwareInterface>
    </joint>
    <actuator name="right_rear_body_to_coxa_actuator">
      <hardwareInterface>hardware_interface/EffortJointInterface</hardwareInterface>
      <mechanicalReduction>1</mechanicalReduction>
    </actuator>
  </transmission>
  <joint name="right_rear_coxa_to_femur_joint" type="revolute">
    <parent link="right_rear_coxa"/>
    <origin rpy="0 0 0" xyz="0 -0.019 -0.0365"/>
    <child link="right_rear_femur"/>
    <axis xyz="1 0 0"/>
    <limit effort="0.5295591" lower="-0.785398163397" upper="0.785398163397" velocity="0.003141593"/>
  </joint>
  <!-- TRANSMITION DEFINITION -->
  <transmission name="right_rear_coxa_to_femur_transmition">
    <type>transmission_interface/SimpleTransmission</type>
    <joint name="right_rear_coxa_to_femur_joint">
      <hardwareInterface>hardware_interface/EffortJointInterface</hardwareInterface>
    </joint>
    <actuator name="right_rear_coxa_to_femur_actuator">
      <hardwareInterface>hardware_interface/EffortJointInterface</hardwareInterface>
      <mechanicalReduction>1</mechanicalReduction>
    </actuator>
  </transmission>
  <joint name="right_rear_femur_to_tibia_joint" type="revolute">
    <parent link="right_rear_femur"/>
    <origin rpy="0 0 0" xyz="0 0 -0.057"/>
    <child link="right_rear_tibia"/>
    <axis xyz="1 0 0"/>
    <limit effort="0.5295591" lower="0.0" upper="2.35619449019" velocity="0.003141593"/>
  </joint>
  <!-- TRANSMITION DEFINITION -->
  <transmission name="right_rear_femur_to_tibia_transmition">
    <type>transmission_interface/SimpleTransmission</type>
    <joint name="right_rear_femur_to_tibia_joint">
      <hardwareInterface>hardware_interface/EffortJointInterface</hardwareInterface>
    </joint>
    <actuator name="right_rear_femur_to_tibia_actuator">
      <hardwareInterface>hardware_interface/EffortJointInterface</hardwareInterface>
      <mechanicalReduction>1</mechanicalReduction>
    </actuator>
  </transmission>
  <gazebo reference="right_rear_coxa">
    <mu1>0.9</mu1>
    <mu2>0.6</mu2>
  </gazebo>
  <gazebo>
    <plugin filename="libgazebo_ros_control.so" name="gazebo_ros_control">
      <robotNamespace>/twt</robotNamespace>
    </plugin>
  </gazebo>
  <gazebo reference="base_link">
    <gravity>0</gravity>
  </gazebo>
</robot>

