<?xml version="1.0" encoding="utf-8"?>
<!-- =================================================================================== -->
<!-- |    This document was autogenerated by xacro from hexapod.urdf.xacro             | -->
<!-- |    EDITING THIS FILE BY HAND IS NOT RECOMMENDED                                 | -->
<!-- =================================================================================== -->
<robot name="hexapod">
  <link name="base_link">
    <visual>
      <geometry>
        <mesh filename="stl/the_walking_thread/frame.stl" scale="1 1 1"/>
      </geometry>
      <origin xyz="0 0 0"/>
    </visual>
    <collision>
      <geometry>
        <box size="0.3618                      0.136                      0.052"/>
      </geometry>
    </collision>
    <inertial>
      <mass value="0.12138"/>
      <inertia ixx="0.2" ixy="0.2" ixz="0.2" iyy="0.2" iyz="0.2" izz="0.2"/>
    </inertial>
  </link>
  <link name="left_front_coxa">
    <visual>
      <geometry>
        <mesh filename="stl/the_walking_thread/coxa.stl" scale="1 1 1"/>
      </geometry>
      <mesh filename="stl/the_walking_thread/coxa.stl" scale="1 1 1"/>
      <origin rpy="1.57079632679 0 0" xyz="0 0 -0.018"/>
    </visual>
    <collision>
      <geometry>
        <sphere radius="0.02"/>
      </geometry>
      <origin rpy="0 0 0" xyz="0 0 -0.026"/>
    </collision>
    <inertial>
      <mass value="0.12138"/>
      <inertia ixx="0.2" ixy="0.2" ixz="0.2" iyy="0.2" iyz="0.2" izz="0.2"/>
    </inertial>
  </link>
  <link name="left_front_femur">
    <visual>
      <geometry>
        <mesh filename="stl/the_walking_thread/femur.stl" scale="1 1 1"/>
      </geometry>
      <mesh filename="stl/the_walking_thread/femur.stl" scale="1 1 1"/>
      <origin rpy="1.57079632679 0 0" xyz="0 0 -0.0275"/>
    </visual>
    <collision>
      <geometry>
        <sphere radius="0.02"/>
      </geometry>
      <origin rpy="0 0 0" xyz="0 0 -0.045"/>
    </collision>
    <inertial>
      <mass value="0.12138"/>
      <inertia ixx="0.2" ixy="0.2" ixz="0.2" iyy="0.2" iyz="0.2" izz="0.2"/>
    </inertial>
  </link>
  <link name="left_front_tibia">
    <visual>
      <geometry>
        <mesh filename="stl/the_walking_thread/tibia.stl" scale="1 1 1"/>
      </geometry>
      <mesh filename="stl/the_walking_thread/tibia.stl" scale="1 1 1"/>
      <origin rpy="1.57079632679 0 0" xyz="0 0 -0.08165"/>
    </visual>
    <collision>
      <geometry>
        <sphere radius="0.0065"/>
      </geometry>
      <origin rpy="0 0 0" xyz="0 0 -0.16005"/>
    </collision>
    <inertial>
      <mass value="0.12138"/>
      <inertia ixx="0.2" ixy="0.2" ixz="0.2" iyy="0.2" iyz="0.2" izz="0.2"/>
    </inertial>
  </link>
  <joint name="left_front_base_link_to_coxa_joint" type="revolute">
    <parent link="base_link"/>
    <origin rpy="-1.57079632679 0 3.14159265359" xyz="0.1809                        0.068                        0"/>
    <!-- ${reflect_multiplier*pi/2} -->
    <child link="left_front_coxa"/>
    <axis xyz="0 1 0"/>
    <limit effort="0.5295591" lower="-0.785398163397" upper="0.785398163397" velocity="0.003141593"/>
  </joint>
  <!-- TRANSMITION DEFINITION -->
  <transmission name="left_front_base_link_to_coxa_transmition" type="SimpleTransmission">
    <type>transmission_interface/SimpleTransmission</type>
    <joint name="left_front_base_link_to_coxa_joint">
      <hardwareInterface>EffortJointInterface</hardwareInterface>
    </joint>
    <actuator name="left_front_base_link_to_coxa_actuator">
      <hardwareInterface>EffortJointInterface</hardwareInterface>
      <mechanicalReduction>1</mechanicalReduction>
    </actuator>
  </transmission>
  <joint name="left_front_coxa_to_femur_joint" type="revolute">
    <!-- ${reflect_multiplier*pi/2} -->
    <parent link="left_front_coxa"/>
    <origin rpy="0 0 0" xyz="0 -0.01730 -0.036"/>
    <child link="left_front_femur"/>
    <axis xyz="1 0 0"/>
    <limit effort="0.5295591" lower="-0.785398163397" upper="0.785398163397" velocity="0.003141593"/>
  </joint>
  <!-- TRANSMITION DEFINITION -->
  <transmission name="left_front_coxa_to_femur_transmition" type="SimpleTransmission">
    <type>transmission_interface/SimpleTransmission</type>
    <joint name="left_front_coxa_to_femur_joint">
      <hardwareInterface>EffortJointInterface</hardwareInterface>
    </joint>
    <actuator name="left_front_coxa_to_femur_actuator">
      <hardwareInterface>EffortJointInterface</hardwareInterface>
      <mechanicalReduction>1</mechanicalReduction>
    </actuator>
  </transmission>
  <joint name="left_front_femur_to_tibia_joint" type="revolute">
    <!-- ${reflect_multiplier*pi/2} -->
    <parent link="left_front_femur"/>
    <origin rpy="0 0 0" xyz="0 0 -0.055"/>
    <child link="left_front_tibia"/>
    <axis xyz="1 0 0"/>
    <limit effort="0.5295591" lower="0.0" upper="2.35619449019" velocity="0.003141593"/>
  </joint>
  <!-- TRANSMITION DEFINITION -->
  <transmission name="left_front_femur_to_tibia_transmition" type="SimpleTransmission">
    <type>transmission_interface/SimpleTransmission</type>
    <joint name="left_front_femur_to_tibia_joint">
      <hardwareInterface>EffortJointInterface</hardwareInterface>
    </joint>
    <actuator name="left_front_femur_to_tibia_actuator">
      <hardwareInterface>EffortJointInterface</hardwareInterface>
      <mechanicalReduction>1</mechanicalReduction>
    </actuator>
  </transmission>
  <link name="left_central_coxa">
    <visual>
      <geometry>
        <mesh filename="stl/the_walking_thread/coxa.stl" scale="1 1 1"/>
      </geometry>
      <mesh filename="stl/the_walking_thread/coxa.stl" scale="1 1 1"/>
      <origin rpy="1.57079632679 0 0" xyz="0 0 -0.018"/>
    </visual>
    <collision>
      <geometry>
        <sphere radius="0.02"/>
      </geometry>
      <origin rpy="0 0 0" xyz="0 0 -0.026"/>
    </collision>
    <inertial>
      <mass value="0.12138"/>
      <inertia ixx="0.2" ixy="0.2" ixz="0.2" iyy="0.2" iyz="0.2" izz="0.2"/>
    </inertial>
  </link>
  <link name="left_central_femur">
    <visual>
      <geometry>
        <mesh filename="stl/the_walking_thread/femur.stl" scale="1 1 1"/>
      </geometry>
      <mesh filename="stl/the_walking_thread/femur.stl" scale="1 1 1"/>
      <origin rpy="1.57079632679 0 0" xyz="0 0 -0.0275"/>
    </visual>
    <collision>
      <geometry>
        <sphere radius="0.02"/>
      </geometry>
      <origin rpy="0 0 0" xyz="0 0 -0.045"/>
    </collision>
    <inertial>
      <mass value="0.12138"/>
      <inertia ixx="0.2" ixy="0.2" ixz="0.2" iyy="0.2" iyz="0.2" izz="0.2"/>
    </inertial>
  </link>
  <link name="left_central_tibia">
    <visual>
      <geometry>
        <mesh filename="stl/the_walking_thread/tibia.stl" scale="1 1 1"/>
      </geometry>
      <mesh filename="stl/the_walking_thread/tibia.stl" scale="1 1 1"/>
      <origin rpy="1.57079632679 0 0" xyz="0 0 -0.08165"/>
    </visual>
    <collision>
      <geometry>
        <sphere radius="0.0065"/>
      </geometry>
      <origin rpy="0 0 0" xyz="0 0 -0.16005"/>
    </collision>
    <inertial>
      <mass value="0.12138"/>
      <inertia ixx="0.2" ixy="0.2" ixz="0.2" iyy="0.2" iyz="0.2" izz="0.2"/>
    </inertial>
  </link>
  <joint name="left_central_base_link_to_coxa_joint" type="revolute">
    <parent link="base_link"/>
    <origin rpy="-1.57079632679 0 3.14159265359" xyz="0                        0.068                        0"/>
    <!-- ${reflect_multiplier*pi/2} -->
    <child link="left_central_coxa"/>
    <axis xyz="0 1 0"/>
    <limit effort="0.5295591" lower="-0.785398163397" upper="0.785398163397" velocity="0.003141593"/>
  </joint>
  <!-- TRANSMITION DEFINITION -->
  <transmission name="left_central_base_link_to_coxa_transmition" type="SimpleTransmission">
    <type>transmission_interface/SimpleTransmission</type>
    <joint name="left_central_base_link_to_coxa_joint">
      <hardwareInterface>EffortJointInterface</hardwareInterface>
    </joint>
    <actuator name="left_central_base_link_to_coxa_actuator">
      <hardwareInterface>EffortJointInterface</hardwareInterface>
      <mechanicalReduction>1</mechanicalReduction>
    </actuator>
  </transmission>
  <joint name="left_central_coxa_to_femur_joint" type="revolute">
    <!-- ${reflect_multiplier*pi/2} -->
    <parent link="left_central_coxa"/>
    <origin rpy="0 0 0" xyz="0 -0.01730 -0.036"/>
    <child link="left_central_femur"/>
    <axis xyz="1 0 0"/>
    <limit effort="0.5295591" lower="-0.785398163397" upper="0.785398163397" velocity="0.003141593"/>
  </joint>
  <!-- TRANSMITION DEFINITION -->
  <transmission name="left_central_coxa_to_femur_transmition" type="SimpleTransmission">
    <type>transmission_interface/SimpleTransmission</type>
    <joint name="left_central_coxa_to_femur_joint">
      <hardwareInterface>EffortJointInterface</hardwareInterface>
    </joint>
    <actuator name="left_central_coxa_to_femur_actuator">
      <hardwareInterface>EffortJointInterface</hardwareInterface>
      <mechanicalReduction>1</mechanicalReduction>
    </actuator>
  </transmission>
  <joint name="left_central_femur_to_tibia_joint" type="revolute">
    <!-- ${reflect_multiplier*pi/2} -->
    <parent link="left_central_femur"/>
    <origin rpy="0 0 0" xyz="0 0 -0.055"/>
    <child link="left_central_tibia"/>
    <axis xyz="1 0 0"/>
    <limit effort="0.5295591" lower="0.0" upper="2.35619449019" velocity="0.003141593"/>
  </joint>
  <!-- TRANSMITION DEFINITION -->
  <transmission name="left_central_femur_to_tibia_transmition" type="SimpleTransmission">
    <type>transmission_interface/SimpleTransmission</type>
    <joint name="left_central_femur_to_tibia_joint">
      <hardwareInterface>EffortJointInterface</hardwareInterface>
    </joint>
    <actuator name="left_central_femur_to_tibia_actuator">
      <hardwareInterface>EffortJointInterface</hardwareInterface>
      <mechanicalReduction>1</mechanicalReduction>
    </actuator>
  </transmission>
  <link name="left_rear_coxa">
    <visual>
      <geometry>
        <mesh filename="stl/the_walking_thread/coxa.stl" scale="1 1 1"/>
      </geometry>
      <mesh filename="stl/the_walking_thread/coxa.stl" scale="1 1 1"/>
      <origin rpy="1.57079632679 0 0" xyz="0 0 -0.018"/>
    </visual>
    <collision>
      <geometry>
        <sphere radius="0.02"/>
      </geometry>
      <origin rpy="0 0 0" xyz="0 0 -0.026"/>
    </collision>
    <inertial>
      <mass value="0.12138"/>
      <inertia ixx="0.2" ixy="0.2" ixz="0.2" iyy="0.2" iyz="0.2" izz="0.2"/>
    </inertial>
  </link>
  <link name="left_rear_femur">
    <visual>
      <geometry>
        <mesh filename="stl/the_walking_thread/femur.stl" scale="1 1 1"/>
      </geometry>
      <mesh filename="stl/the_walking_thread/femur.stl" scale="1 1 1"/>
      <origin rpy="1.57079632679 0 0" xyz="0 0 -0.0275"/>
    </visual>
    <collision>
      <geometry>
        <sphere radius="0.02"/>
      </geometry>
      <origin rpy="0 0 0" xyz="0 0 -0.045"/>
    </collision>
    <inertial>
      <mass value="0.12138"/>
      <inertia ixx="0.2" ixy="0.2" ixz="0.2" iyy="0.2" iyz="0.2" izz="0.2"/>
    </inertial>
  </link>
  <link name="left_rear_tibia">
    <visual>
      <geometry>
        <mesh filename="stl/the_walking_thread/tibia.stl" scale="1 1 1"/>
      </geometry>
      <mesh filename="stl/the_walking_thread/tibia.stl" scale="1 1 1"/>
      <origin rpy="1.57079632679 0 0" xyz="0 0 -0.08165"/>
    </visual>
    <collision>
      <geometry>
        <sphere radius="0.0065"/>
      </geometry>
      <origin rpy="0 0 0" xyz="0 0 -0.16005"/>
    </collision>
    <inertial>
      <mass value="0.12138"/>
      <inertia ixx="0.2" ixy="0.2" ixz="0.2" iyy="0.2" iyz="0.2" izz="0.2"/>
    </inertial>
  </link>
  <joint name="left_rear_base_link_to_coxa_joint" type="revolute">
    <parent link="base_link"/>
    <origin rpy="-1.57079632679 0 3.14159265359" xyz="-0.1809                        0.068                        0"/>
    <!-- ${reflect_multiplier*pi/2} -->
    <child link="left_rear_coxa"/>
    <axis xyz="0 1 0"/>
    <limit effort="0.5295591" lower="-0.785398163397" upper="0.785398163397" velocity="0.003141593"/>
  </joint>
  <!-- TRANSMITION DEFINITION -->
  <transmission name="left_rear_base_link_to_coxa_transmition" type="SimpleTransmission">
    <type>transmission_interface/SimpleTransmission</type>
    <joint name="left_rear_base_link_to_coxa_joint">
      <hardwareInterface>EffortJointInterface</hardwareInterface>
    </joint>
    <actuator name="left_rear_base_link_to_coxa_actuator">
      <hardwareInterface>EffortJointInterface</hardwareInterface>
      <mechanicalReduction>1</mechanicalReduction>
    </actuator>
  </transmission>
  <joint name="left_rear_coxa_to_femur_joint" type="revolute">
    <!-- ${reflect_multiplier*pi/2} -->
    <parent link="left_rear_coxa"/>
    <origin rpy="0 0 0" xyz="0 -0.01730 -0.036"/>
    <child link="left_rear_femur"/>
    <axis xyz="1 0 0"/>
    <limit effort="0.5295591" lower="-0.785398163397" upper="0.785398163397" velocity="0.003141593"/>
  </joint>
  <!-- TRANSMITION DEFINITION -->
  <transmission name="left_rear_coxa_to_femur_transmition" type="SimpleTransmission">
    <type>transmission_interface/SimpleTransmission</type>
    <joint name="left_rear_coxa_to_femur_joint">
      <hardwareInterface>EffortJointInterface</hardwareInterface>
    </joint>
    <actuator name="left_rear_coxa_to_femur_actuator">
      <hardwareInterface>EffortJointInterface</hardwareInterface>
      <mechanicalReduction>1</mechanicalReduction>
    </actuator>
  </transmission>
  <joint name="left_rear_femur_to_tibia_joint" type="revolute">
    <!-- ${reflect_multiplier*pi/2} -->
    <parent link="left_rear_femur"/>
    <origin rpy="0 0 0" xyz="0 0 -0.055"/>
    <child link="left_rear_tibia"/>
    <axis xyz="1 0 0"/>
    <limit effort="0.5295591" lower="0.0" upper="2.35619449019" velocity="0.003141593"/>
  </joint>
  <!-- TRANSMITION DEFINITION -->
  <transmission name="left_rear_femur_to_tibia_transmition" type="SimpleTransmission">
    <type>transmission_interface/SimpleTransmission</type>
    <joint name="left_rear_femur_to_tibia_joint">
      <hardwareInterface>EffortJointInterface</hardwareInterface>
    </joint>
    <actuator name="left_rear_femur_to_tibia_actuator">
      <hardwareInterface>EffortJointInterface</hardwareInterface>
      <mechanicalReduction>1</mechanicalReduction>
    </actuator>
  </transmission>
  <link name="right_front_coxa">
    <visual>
      <geometry>
        <mesh filename="stl/the_walking_thread/coxa.stl" scale="1 1 1"/>
      </geometry>
      <mesh filename="stl/the_walking_thread/coxa.stl" scale="1 1 1"/>
      <origin rpy="1.57079632679 0 0" xyz="0 0 -0.018"/>
    </visual>
    <collision>
      <geometry>
        <sphere radius="0.02"/>
      </geometry>
      <origin rpy="0 0 0" xyz="0 0 -0.026"/>
    </collision>
    <inertial>
      <mass value="0.12138"/>
      <inertia ixx="0.2" ixy="0.2" ixz="0.2" iyy="0.2" iyz="0.2" izz="0.2"/>
    </inertial>
  </link>
  <link name="right_front_femur">
    <visual>
      <geometry>
        <mesh filename="stl/the_walking_thread/femur.stl" scale="1 1 1"/>
      </geometry>
      <mesh filename="stl/the_walking_thread/femur.stl" scale="1 1 1"/>
      <origin rpy="1.57079632679 0 0" xyz="0 0 -0.0275"/>
    </visual>
    <collision>
      <geometry>
        <sphere radius="0.02"/>
      </geometry>
      <origin rpy="0 0 0" xyz="0 0 -0.045"/>
    </collision>
    <inertial>
      <mass value="0.12138"/>
      <inertia ixx="0.2" ixy="0.2" ixz="0.2" iyy="0.2" iyz="0.2" izz="0.2"/>
    </inertial>
  </link>
  <link name="right_front_tibia">
    <visual>
      <geometry>
        <mesh filename="stl/the_walking_thread/tibia.stl" scale="1 1 1"/>
      </geometry>
      <mesh filename="stl/the_walking_thread/tibia.stl" scale="1 1 1"/>
      <origin rpy="1.57079632679 0 0" xyz="0 0 -0.08165"/>
    </visual>
    <collision>
      <geometry>
        <sphere radius="0.0065"/>
      </geometry>
      <origin rpy="0 0 0" xyz="0 0 -0.16005"/>
    </collision>
    <inertial>
      <mass value="0.12138"/>
      <inertia ixx="0.2" ixy="0.2" ixz="0.2" iyy="0.2" iyz="0.2" izz="0.2"/>
    </inertial>
  </link>
  <joint name="right_front_base_link_to_coxa_joint" type="revolute">
    <parent link="base_link"/>
    <origin rpy="-1.57079632679 0 0.0" xyz="0.1809                        -0.068                        0"/>
    <!-- ${reflect_multiplier*pi/2} -->
    <child link="right_front_coxa"/>
    <axis xyz="0 -1 0"/>
    <limit effort="0.5295591" lower="-0.785398163397" upper="0.785398163397" velocity="0.003141593"/>
  </joint>
  <!-- TRANSMITION DEFINITION -->
  <transmission name="right_front_base_link_to_coxa_transmition" type="SimpleTransmission">
    <type>transmission_interface/SimpleTransmission</type>
    <joint name="right_front_base_link_to_coxa_joint">
      <hardwareInterface>EffortJointInterface</hardwareInterface>
    </joint>
    <actuator name="right_front_base_link_to_coxa_actuator">
      <hardwareInterface>EffortJointInterface</hardwareInterface>
      <mechanicalReduction>1</mechanicalReduction>
    </actuator>
  </transmission>
  <joint name="right_front_coxa_to_femur_joint" type="revolute">
    <!-- ${reflect_multiplier*pi/2} -->
    <parent link="right_front_coxa"/>
    <origin rpy="0 0 0" xyz="0 -0.01730 -0.036"/>
    <child link="right_front_femur"/>
    <axis xyz="1 0 0"/>
    <limit effort="0.5295591" lower="-0.785398163397" upper="0.785398163397" velocity="0.003141593"/>
  </joint>
  <!-- TRANSMITION DEFINITION -->
  <transmission name="right_front_coxa_to_femur_transmition" type="SimpleTransmission">
    <type>transmission_interface/SimpleTransmission</type>
    <joint name="right_front_coxa_to_femur_joint">
      <hardwareInterface>EffortJointInterface</hardwareInterface>
    </joint>
    <actuator name="right_front_coxa_to_femur_actuator">
      <hardwareInterface>EffortJointInterface</hardwareInterface>
      <mechanicalReduction>1</mechanicalReduction>
    </actuator>
  </transmission>
  <joint name="right_front_femur_to_tibia_joint" type="revolute">
    <!-- ${reflect_multiplier*pi/2} -->
    <parent link="right_front_femur"/>
    <origin rpy="0 0 0" xyz="0 0 -0.055"/>
    <child link="right_front_tibia"/>
    <axis xyz="1 0 0"/>
    <limit effort="0.5295591" lower="0.0" upper="2.35619449019" velocity="0.003141593"/>
  </joint>
  <!-- TRANSMITION DEFINITION -->
  <transmission name="right_front_femur_to_tibia_transmition" type="SimpleTransmission">
    <type>transmission_interface/SimpleTransmission</type>
    <joint name="right_front_femur_to_tibia_joint">
      <hardwareInterface>EffortJointInterface</hardwareInterface>
    </joint>
    <actuator name="right_front_femur_to_tibia_actuator">
      <hardwareInterface>EffortJointInterface</hardwareInterface>
      <mechanicalReduction>1</mechanicalReduction>
    </actuator>
  </transmission>
  <link name="right_central_coxa">
    <visual>
      <geometry>
        <mesh filename="stl/the_walking_thread/coxa.stl" scale="1 1 1"/>
      </geometry>
      <mesh filename="stl/the_walking_thread/coxa.stl" scale="1 1 1"/>
      <origin rpy="1.57079632679 0 0" xyz="0 0 -0.018"/>
    </visual>
    <collision>
      <geometry>
        <sphere radius="0.02"/>
      </geometry>
      <origin rpy="0 0 0" xyz="0 0 -0.026"/>
    </collision>
    <inertial>
      <mass value="0.12138"/>
      <inertia ixx="0.2" ixy="0.2" ixz="0.2" iyy="0.2" iyz="0.2" izz="0.2"/>
    </inertial>
  </link>
  <link name="right_central_femur">
    <visual>
      <geometry>
        <mesh filename="stl/the_walking_thread/femur.stl" scale="1 1 1"/>
      </geometry>
      <mesh filename="stl/the_walking_thread/femur.stl" scale="1 1 1"/>
      <origin rpy="1.57079632679 0 0" xyz="0 0 -0.0275"/>
    </visual>
    <collision>
      <geometry>
        <sphere radius="0.02"/>
      </geometry>
      <origin rpy="0 0 0" xyz="0 0 -0.045"/>
    </collision>
    <inertial>
      <mass value="0.12138"/>
      <inertia ixx="0.2" ixy="0.2" ixz="0.2" iyy="0.2" iyz="0.2" izz="0.2"/>
    </inertial>
  </link>
  <link name="right_central_tibia">
    <visual>
      <geometry>
        <mesh filename="stl/the_walking_thread/tibia.stl" scale="1 1 1"/>
      </geometry>
      <mesh filename="stl/the_walking_thread/tibia.stl" scale="1 1 1"/>
      <origin rpy="1.57079632679 0 0" xyz="0 0 -0.08165"/>
    </visual>
    <collision>
      <geometry>
        <sphere radius="0.0065"/>
      </geometry>
      <origin rpy="0 0 0" xyz="0 0 -0.16005"/>
    </collision>
    <inertial>
      <mass value="0.12138"/>
      <inertia ixx="0.2" ixy="0.2" ixz="0.2" iyy="0.2" iyz="0.2" izz="0.2"/>
    </inertial>
  </link>
  <joint name="right_central_base_link_to_coxa_joint" type="revolute">
    <parent link="base_link"/>
    <origin rpy="-1.57079632679 0 0.0" xyz="0                        -0.068                        0"/>
    <!-- ${reflect_multiplier*pi/2} -->
    <child link="right_central_coxa"/>
    <axis xyz="0 -1 0"/>
    <limit effort="0.5295591" lower="-0.785398163397" upper="0.785398163397" velocity="0.003141593"/>
  </joint>
  <!-- TRANSMITION DEFINITION -->
  <transmission name="right_central_base_link_to_coxa_transmition" type="SimpleTransmission">
    <type>transmission_interface/SimpleTransmission</type>
    <joint name="right_central_base_link_to_coxa_joint">
      <hardwareInterface>EffortJointInterface</hardwareInterface>
    </joint>
    <actuator name="right_central_base_link_to_coxa_actuator">
      <hardwareInterface>EffortJointInterface</hardwareInterface>
      <mechanicalReduction>1</mechanicalReduction>
    </actuator>
  </transmission>
  <joint name="right_central_coxa_to_femur_joint" type="revolute">
    <!-- ${reflect_multiplier*pi/2} -->
    <parent link="right_central_coxa"/>
    <origin rpy="0 0 0" xyz="0 -0.01730 -0.036"/>
    <child link="right_central_femur"/>
    <axis xyz="1 0 0"/>
    <limit effort="0.5295591" lower="-0.785398163397" upper="0.785398163397" velocity="0.003141593"/>
  </joint>
  <!-- TRANSMITION DEFINITION -->
  <transmission name="right_central_coxa_to_femur_transmition" type="SimpleTransmission">
    <type>transmission_interface/SimpleTransmission</type>
    <joint name="right_central_coxa_to_femur_joint">
      <hardwareInterface>EffortJointInterface</hardwareInterface>
    </joint>
    <actuator name="right_central_coxa_to_femur_actuator">
      <hardwareInterface>EffortJointInterface</hardwareInterface>
      <mechanicalReduction>1</mechanicalReduction>
    </actuator>
  </transmission>
  <joint name="right_central_femur_to_tibia_joint" type="revolute">
    <!-- ${reflect_multiplier*pi/2} -->
    <parent link="right_central_femur"/>
    <origin rpy="0 0 0" xyz="0 0 -0.055"/>
    <child link="right_central_tibia"/>
    <axis xyz="1 0 0"/>
    <limit effort="0.5295591" lower="0.0" upper="2.35619449019" velocity="0.003141593"/>
  </joint>
  <!-- TRANSMITION DEFINITION -->
  <transmission name="right_central_femur_to_tibia_transmition" type="SimpleTransmission">
    <type>transmission_interface/SimpleTransmission</type>
    <joint name="right_central_femur_to_tibia_joint">
      <hardwareInterface>EffortJointInterface</hardwareInterface>
    </joint>
    <actuator name="right_central_femur_to_tibia_actuator">
      <hardwareInterface>EffortJointInterface</hardwareInterface>
      <mechanicalReduction>1</mechanicalReduction>
    </actuator>
  </transmission>
  <link name="right_rear_coxa">
    <visual>
      <geometry>
        <mesh filename="stl/the_walking_thread/coxa.stl" scale="1 1 1"/>
      </geometry>
      <mesh filename="stl/the_walking_thread/coxa.stl" scale="1 1 1"/>
      <origin rpy="1.57079632679 0 0" xyz="0 0 -0.018"/>
    </visual>
    <collision>
      <geometry>
        <sphere radius="0.02"/>
      </geometry>
      <origin rpy="0 0 0" xyz="0 0 -0.026"/>
    </collision>
    <inertial>
      <mass value="0.12138"/>
      <inertia ixx="0.2" ixy="0.2" ixz="0.2" iyy="0.2" iyz="0.2" izz="0.2"/>
    </inertial>
  </link>
  <link name="right_rear_femur">
    <visual>
      <geometry>
        <mesh filename="stl/the_walking_thread/femur.stl" scale="1 1 1"/>
      </geometry>
      <mesh filename="stl/the_walking_thread/femur.stl" scale="1 1 1"/>
      <origin rpy="1.57079632679 0 0" xyz="0 0 -0.0275"/>
    </visual>
    <collision>
      <geometry>
        <sphere radius="0.02"/>
      </geometry>
      <origin rpy="0 0 0" xyz="0 0 -0.045"/>
    </collision>
    <inertial>
      <mass value="0.12138"/>
      <inertia ixx="0.2" ixy="0.2" ixz="0.2" iyy="0.2" iyz="0.2" izz="0.2"/>
    </inertial>
  </link>
  <link name="right_rear_tibia">
    <visual>
      <geometry>
        <mesh filename="stl/the_walking_thread/tibia.stl" scale="1 1 1"/>
      </geometry>
      <mesh filename="stl/the_walking_thread/tibia.stl" scale="1 1 1"/>
      <origin rpy="1.57079632679 0 0" xyz="0 0 -0.08165"/>
    </visual>
    <collision>
      <geometry>
        <sphere radius="0.0065"/>
      </geometry>
      <origin rpy="0 0 0" xyz="0 0 -0.16005"/>
    </collision>
    <inertial>
      <mass value="0.12138"/>
      <inertia ixx="0.2" ixy="0.2" ixz="0.2" iyy="0.2" iyz="0.2" izz="0.2"/>
    </inertial>
  </link>
  <joint name="right_rear_base_link_to_coxa_joint" type="revolute">
    <parent link="base_link"/>
    <origin rpy="-1.57079632679 0 0.0" xyz="-0.1809                        -0.068                        0"/>
    <!-- ${reflect_multiplier*pi/2} -->
    <child link="right_rear_coxa"/>
    <axis xyz="0 -1 0"/>
    <limit effort="0.5295591" lower="-0.785398163397" upper="0.785398163397" velocity="0.003141593"/>
  </joint>
  <!-- TRANSMITION DEFINITION -->
  <transmission name="right_rear_base_link_to_coxa_transmition" type="SimpleTransmission">
    <type>transmission_interface/SimpleTransmission</type>
    <joint name="right_rear_base_link_to_coxa_joint">
      <hardwareInterface>EffortJointInterface</hardwareInterface>
    </joint>
    <actuator name="right_rear_base_link_to_coxa_actuator">
      <hardwareInterface>EffortJointInterface</hardwareInterface>
      <mechanicalReduction>1</mechanicalReduction>
    </actuator>
  </transmission>
  <joint name="right_rear_coxa_to_femur_joint" type="revolute">
    <!-- ${reflect_multiplier*pi/2} -->
    <parent link="right_rear_coxa"/>
    <origin rpy="0 0 0" xyz="0 -0.01730 -0.036"/>
    <child link="right_rear_femur"/>
    <axis xyz="1 0 0"/>
    <limit effort="0.5295591" lower="-0.785398163397" upper="0.785398163397" velocity="0.003141593"/>
  </joint>
  <!-- TRANSMITION DEFINITION -->
  <transmission name="right_rear_coxa_to_femur_transmition" type="SimpleTransmission">
    <type>transmission_interface/SimpleTransmission</type>
    <joint name="right_rear_coxa_to_femur_joint">
      <hardwareInterface>EffortJointInterface</hardwareInterface>
    </joint>
    <actuator name="right_rear_coxa_to_femur_actuator">
      <hardwareInterface>EffortJointInterface</hardwareInterface>
      <mechanicalReduction>1</mechanicalReduction>
    </actuator>
  </transmission>
  <joint name="right_rear_femur_to_tibia_joint" type="revolute">
    <!-- ${reflect_multiplier*pi/2} -->
    <parent link="right_rear_femur"/>
    <origin rpy="0 0 0" xyz="0 0 -0.055"/>
    <child link="right_rear_tibia"/>
    <axis xyz="1 0 0"/>
    <limit effort="0.5295591" lower="0.0" upper="2.35619449019" velocity="0.003141593"/>
  </joint>
  <!-- TRANSMITION DEFINITION -->
  <transmission name="right_rear_femur_to_tibia_transmition" type="SimpleTransmission">
    <type>transmission_interface/SimpleTransmission</type>
    <joint name="right_rear_femur_to_tibia_joint">
      <hardwareInterface>EffortJointInterface</hardwareInterface>
    </joint>
    <actuator name="right_rear_femur_to_tibia_actuator">
      <hardwareInterface>EffortJointInterface</hardwareInterface>
      <mechanicalReduction>1</mechanicalReduction>
    </actuator>
  </transmission>
</robot>

