<?xml version="1.0" encoding="utf-8"?>
<!-- =================================================================================== -->
<!-- |    This document was autogenerated by xacro from hexapod.urdf.xacro             | -->
<!-- |    EDITING THIS FILE BY HAND IS NOT RECOMMENDED                                 | -->
<!-- =================================================================================== -->
<robot name="hexapod">
  <link name="base_link">
    <visual>
      <geometry>
        <box size="0.3 0.15 0.08"/>
      </geometry>
      <origin xyz="0 0 0"/>
    </visual>
    <collision>
      <geometry>
        <box size="0.3 0.15 0.08"/>
      </geometry>
    </collision>
    <inertial>
      <mass value="10"/>
      <inertia ixx="0.2" ixy="0.2" ixz="0.2" iyy="0.2" iyz="0.2" izz="0.2"/>
    </inertial>
  </link>
  <link name="left_front_coxa">
    <visual>
      <geometry>
        <cylinder length="0.01" radius="0.001"/>
      </geometry>
      <origin rpy="0 0 1.57079632679" xyz="0 0 -0.005"/>
    </visual>
    <collision>
      <geometry>
        <sphere radius="0.001"/>
      </geometry>
      <origin rpy="0 0 0" xyz="0 0 -0.0095"/>
    </collision>
    <inertial>
      <mass value="0.2"/>
      <inertia ixx="0.2" ixy="0.2" ixz="0.2" iyy="0.2" iyz="0.2" izz="0.2"/>
    </inertial>
  </link>
  <link name="left_front_femur">
    <visual>
      <geometry>
        <cylinder length="0.2" radius="0.025"/>
      </geometry>
      <origin rpy="0 0 1.57079632679" xyz="0 0 -0.1"/>
    </visual>
    <collision>
      <geometry>
        <sphere radius="0.025"/>
      </geometry>
      <origin rpy="0 0 0" xyz="0 0 -0.1875"/>
    </collision>
    <inertial>
      <mass value="0.2"/>
      <inertia ixx="0.2" ixy="0.2" ixz="0.2" iyy="0.2" iyz="0.2" izz="0.2"/>
    </inertial>
  </link>
  <link name="left_front_tibia">
    <visual>
      <geometry>
        <cylinder length="0.2" radius="0.025"/>
      </geometry>
      <origin rpy="0 0 1.57079632679" xyz="0 0 -0.1"/>
    </visual>
    <collision>
      <geometry>
        <sphere radius="0.025"/>
      </geometry>
      <origin rpy="0 0 0" xyz="0 0 -0.1875"/>
    </collision>
    <inertial>
      <mass value="0.2"/>
      <inertia ixx="0.2" ixy="0.2" ixz="0.2" iyy="0.2" iyz="0.2" izz="0.2"/>
    </inertial>
  </link>
  <joint name="left_front_base_link_to_coxa_joint" type="revolute">
    <parent link="base_link"/>
    <origin rpy="1.57079632679 0 0" xyz="0.15                        0.075                        0"/>
    <child link="left_front_coxa"/>
    <axis xyz="0 -1 0"/>
    <limit effort="0.2" lower="-0.785398163397" upper="0.785398163397" velocity="0.2"/>
  </joint>
  <joint name="left_front_coxa_to_femur_joint" type="revolute">
    <parent link="left_front_coxa"/>
    <origin rpy="0 0 0" xyz="0 0 -0.01"/>
    <child link="left_front_femur"/>
    <axis xyz="1 0 0"/>
    <limit effort="0.2" lower="-0.785398163397" upper="0.785398163397" velocity="0.2"/>
  </joint>
  <joint name="left_front_femur_to_tibia_joint" type="revolute">
    <parent link="left_front_femur"/>
    <origin rpy="0 0 0" xyz="0 0 -0.2"/>
    <child link="left_front_tibia"/>
    <axis xyz="1 0 0"/>
    <limit effort="0.2" lower="-2.35619449019" upper="0.0" velocity="0.2"/>
  </joint>
  <link name="left_central_coxa">
    <visual>
      <geometry>
        <cylinder length="0.01" radius="0.001"/>
      </geometry>
      <origin rpy="0 0 1.57079632679" xyz="0 0 -0.005"/>
    </visual>
    <collision>
      <geometry>
        <sphere radius="0.001"/>
      </geometry>
      <origin rpy="0 0 0" xyz="0 0 -0.0095"/>
    </collision>
    <inertial>
      <mass value="0.2"/>
      <inertia ixx="0.2" ixy="0.2" ixz="0.2" iyy="0.2" iyz="0.2" izz="0.2"/>
    </inertial>
  </link>
  <link name="left_central_femur">
    <visual>
      <geometry>
        <cylinder length="0.2" radius="0.025"/>
      </geometry>
      <origin rpy="0 0 1.57079632679" xyz="0 0 -0.1"/>
    </visual>
    <collision>
      <geometry>
        <sphere radius="0.025"/>
      </geometry>
      <origin rpy="0 0 0" xyz="0 0 -0.1875"/>
    </collision>
    <inertial>
      <mass value="0.2"/>
      <inertia ixx="0.2" ixy="0.2" ixz="0.2" iyy="0.2" iyz="0.2" izz="0.2"/>
    </inertial>
  </link>
  <link name="left_central_tibia">
    <visual>
      <geometry>
        <cylinder length="0.2" radius="0.025"/>
      </geometry>
      <origin rpy="0 0 1.57079632679" xyz="0 0 -0.1"/>
    </visual>
    <collision>
      <geometry>
        <sphere radius="0.025"/>
      </geometry>
      <origin rpy="0 0 0" xyz="0 0 -0.1875"/>
    </collision>
    <inertial>
      <mass value="0.2"/>
      <inertia ixx="0.2" ixy="0.2" ixz="0.2" iyy="0.2" iyz="0.2" izz="0.2"/>
    </inertial>
  </link>
  <joint name="left_central_base_link_to_coxa_joint" type="revolute">
    <parent link="base_link"/>
    <origin rpy="1.57079632679 0 0" xyz="0                        0.075                        0"/>
    <child link="left_central_coxa"/>
    <axis xyz="0 -1 0"/>
    <limit effort="0.2" lower="-0.785398163397" upper="0.785398163397" velocity="0.2"/>
  </joint>
  <joint name="left_central_coxa_to_femur_joint" type="revolute">
    <parent link="left_central_coxa"/>
    <origin rpy="0 0 0" xyz="0 0 -0.01"/>
    <child link="left_central_femur"/>
    <axis xyz="1 0 0"/>
    <limit effort="0.2" lower="-0.785398163397" upper="0.785398163397" velocity="0.2"/>
  </joint>
  <joint name="left_central_femur_to_tibia_joint" type="revolute">
    <parent link="left_central_femur"/>
    <origin rpy="0 0 0" xyz="0 0 -0.2"/>
    <child link="left_central_tibia"/>
    <axis xyz="1 0 0"/>
    <limit effort="0.2" lower="-2.35619449019" upper="0.0" velocity="0.2"/>
  </joint>
  <link name="left_rear_coxa">
    <visual>
      <geometry>
        <cylinder length="0.01" radius="0.001"/>
      </geometry>
      <origin rpy="0 0 1.57079632679" xyz="0 0 -0.005"/>
    </visual>
    <collision>
      <geometry>
        <sphere radius="0.001"/>
      </geometry>
      <origin rpy="0 0 0" xyz="0 0 -0.0095"/>
    </collision>
    <inertial>
      <mass value="0.2"/>
      <inertia ixx="0.2" ixy="0.2" ixz="0.2" iyy="0.2" iyz="0.2" izz="0.2"/>
    </inertial>
  </link>
  <link name="left_rear_femur">
    <visual>
      <geometry>
        <cylinder length="0.2" radius="0.025"/>
      </geometry>
      <origin rpy="0 0 1.57079632679" xyz="0 0 -0.1"/>
    </visual>
    <collision>
      <geometry>
        <sphere radius="0.025"/>
      </geometry>
      <origin rpy="0 0 0" xyz="0 0 -0.1875"/>
    </collision>
    <inertial>
      <mass value="0.2"/>
      <inertia ixx="0.2" ixy="0.2" ixz="0.2" iyy="0.2" iyz="0.2" izz="0.2"/>
    </inertial>
  </link>
  <link name="left_rear_tibia">
    <visual>
      <geometry>
        <cylinder length="0.2" radius="0.025"/>
      </geometry>
      <origin rpy="0 0 1.57079632679" xyz="0 0 -0.1"/>
    </visual>
    <collision>
      <geometry>
        <sphere radius="0.025"/>
      </geometry>
      <origin rpy="0 0 0" xyz="0 0 -0.1875"/>
    </collision>
    <inertial>
      <mass value="0.2"/>
      <inertia ixx="0.2" ixy="0.2" ixz="0.2" iyy="0.2" iyz="0.2" izz="0.2"/>
    </inertial>
  </link>
  <joint name="left_rear_base_link_to_coxa_joint" type="revolute">
    <parent link="base_link"/>
    <origin rpy="1.57079632679 0 0" xyz="-0.15                        0.075                        0"/>
    <child link="left_rear_coxa"/>
    <axis xyz="0 -1 0"/>
    <limit effort="0.2" lower="-0.785398163397" upper="0.785398163397" velocity="0.2"/>
  </joint>
  <joint name="left_rear_coxa_to_femur_joint" type="revolute">
    <parent link="left_rear_coxa"/>
    <origin rpy="0 0 0" xyz="0 0 -0.01"/>
    <child link="left_rear_femur"/>
    <axis xyz="1 0 0"/>
    <limit effort="0.2" lower="-0.785398163397" upper="0.785398163397" velocity="0.2"/>
  </joint>
  <joint name="left_rear_femur_to_tibia_joint" type="revolute">
    <parent link="left_rear_femur"/>
    <origin rpy="0 0 0" xyz="0 0 -0.2"/>
    <child link="left_rear_tibia"/>
    <axis xyz="1 0 0"/>
    <limit effort="0.2" lower="-2.35619449019" upper="0.0" velocity="0.2"/>
  </joint>
  <link name="right_front_coxa">
    <visual>
      <geometry>
        <cylinder length="0.01" radius="0.001"/>
      </geometry>
      <origin rpy="0 0 1.57079632679" xyz="0 0 -0.005"/>
    </visual>
    <collision>
      <geometry>
        <sphere radius="0.001"/>
      </geometry>
      <origin rpy="0 0 0" xyz="0 0 -0.0095"/>
    </collision>
    <inertial>
      <mass value="0.2"/>
      <inertia ixx="0.2" ixy="0.2" ixz="0.2" iyy="0.2" iyz="0.2" izz="0.2"/>
    </inertial>
  </link>
  <link name="right_front_femur">
    <visual>
      <geometry>
        <cylinder length="0.2" radius="0.025"/>
      </geometry>
      <origin rpy="0 0 1.57079632679" xyz="0 0 -0.1"/>
    </visual>
    <collision>
      <geometry>
        <sphere radius="0.025"/>
      </geometry>
      <origin rpy="0 0 0" xyz="0 0 -0.1875"/>
    </collision>
    <inertial>
      <mass value="0.2"/>
      <inertia ixx="0.2" ixy="0.2" ixz="0.2" iyy="0.2" iyz="0.2" izz="0.2"/>
    </inertial>
  </link>
  <link name="right_front_tibia">
    <visual>
      <geometry>
        <cylinder length="0.2" radius="0.025"/>
      </geometry>
      <origin rpy="0 0 1.57079632679" xyz="0 0 -0.1"/>
    </visual>
    <collision>
      <geometry>
        <sphere radius="0.025"/>
      </geometry>
      <origin rpy="0 0 0" xyz="0 0 -0.1875"/>
    </collision>
    <inertial>
      <mass value="0.2"/>
      <inertia ixx="0.2" ixy="0.2" ixz="0.2" iyy="0.2" iyz="0.2" izz="0.2"/>
    </inertial>
  </link>
  <joint name="right_front_base_link_to_coxa_joint" type="revolute">
    <parent link="base_link"/>
    <origin rpy="-1.57079632679 0 0" xyz="0.15                        -0.075                        0"/>
    <child link="right_front_coxa"/>
    <axis xyz="0 -1 0"/>
    <limit effort="0.2" lower="-0.785398163397" upper="0.785398163397" velocity="0.2"/>
  </joint>
  <joint name="right_front_coxa_to_femur_joint" type="revolute">
    <parent link="right_front_coxa"/>
    <origin rpy="0 0 0" xyz="0 0 -0.01"/>
    <child link="right_front_femur"/>
    <axis xyz="-1 0 0"/>
    <limit effort="0.2" lower="-0.785398163397" upper="0.785398163397" velocity="0.2"/>
  </joint>
  <joint name="right_front_femur_to_tibia_joint" type="revolute">
    <parent link="right_front_femur"/>
    <origin rpy="0 0 0" xyz="0 0 -0.2"/>
    <child link="right_front_tibia"/>
    <axis xyz="-1 0 0"/>
    <limit effort="0.2" lower="-2.35619449019" upper="0.0" velocity="0.2"/>
  </joint>
  <link name="right_central_coxa">
    <visual>
      <geometry>
        <cylinder length="0.01" radius="0.001"/>
      </geometry>
      <origin rpy="0 0 1.57079632679" xyz="0 0 -0.005"/>
    </visual>
    <collision>
      <geometry>
        <sphere radius="0.001"/>
      </geometry>
      <origin rpy="0 0 0" xyz="0 0 -0.0095"/>
    </collision>
    <inertial>
      <mass value="0.2"/>
      <inertia ixx="0.2" ixy="0.2" ixz="0.2" iyy="0.2" iyz="0.2" izz="0.2"/>
    </inertial>
  </link>
  <link name="right_central_femur">
    <visual>
      <geometry>
        <cylinder length="0.2" radius="0.025"/>
      </geometry>
      <origin rpy="0 0 1.57079632679" xyz="0 0 -0.1"/>
    </visual>
    <collision>
      <geometry>
        <sphere radius="0.025"/>
      </geometry>
      <origin rpy="0 0 0" xyz="0 0 -0.1875"/>
    </collision>
    <inertial>
      <mass value="0.2"/>
      <inertia ixx="0.2" ixy="0.2" ixz="0.2" iyy="0.2" iyz="0.2" izz="0.2"/>
    </inertial>
  </link>
  <link name="right_central_tibia">
    <visual>
      <geometry>
        <cylinder length="0.2" radius="0.025"/>
      </geometry>
      <origin rpy="0 0 1.57079632679" xyz="0 0 -0.1"/>
    </visual>
    <collision>
      <geometry>
        <sphere radius="0.025"/>
      </geometry>
      <origin rpy="0 0 0" xyz="0 0 -0.1875"/>
    </collision>
    <inertial>
      <mass value="0.2"/>
      <inertia ixx="0.2" ixy="0.2" ixz="0.2" iyy="0.2" iyz="0.2" izz="0.2"/>
    </inertial>
  </link>
  <joint name="right_central_base_link_to_coxa_joint" type="revolute">
    <parent link="base_link"/>
    <origin rpy="-1.57079632679 0 0" xyz="0                        -0.075                        0"/>
    <child link="right_central_coxa"/>
    <axis xyz="0 -1 0"/>
    <limit effort="0.2" lower="-0.785398163397" upper="0.785398163397" velocity="0.2"/>
  </joint>
  <joint name="right_central_coxa_to_femur_joint" type="revolute">
    <parent link="right_central_coxa"/>
    <origin rpy="0 0 0" xyz="0 0 -0.01"/>
    <child link="right_central_femur"/>
    <axis xyz="-1 0 0"/>
    <limit effort="0.2" lower="-0.785398163397" upper="0.785398163397" velocity="0.2"/>
  </joint>
  <joint name="right_central_femur_to_tibia_joint" type="revolute">
    <parent link="right_central_femur"/>
    <origin rpy="0 0 0" xyz="0 0 -0.2"/>
    <child link="right_central_tibia"/>
    <axis xyz="-1 0 0"/>
    <limit effort="0.2" lower="-2.35619449019" upper="0.0" velocity="0.2"/>
  </joint>
  <link name="right_rear_coxa">
    <visual>
      <geometry>
        <cylinder length="0.01" radius="0.001"/>
      </geometry>
      <origin rpy="0 0 1.57079632679" xyz="0 0 -0.005"/>
    </visual>
    <collision>
      <geometry>
        <sphere radius="0.001"/>
      </geometry>
      <origin rpy="0 0 0" xyz="0 0 -0.0095"/>
    </collision>
    <inertial>
      <mass value="0.2"/>
      <inertia ixx="0.2" ixy="0.2" ixz="0.2" iyy="0.2" iyz="0.2" izz="0.2"/>
    </inertial>
  </link>
  <link name="right_rear_femur">
    <visual>
      <geometry>
        <cylinder length="0.2" radius="0.025"/>
      </geometry>
      <origin rpy="0 0 1.57079632679" xyz="0 0 -0.1"/>
    </visual>
    <collision>
      <geometry>
        <sphere radius="0.025"/>
      </geometry>
      <origin rpy="0 0 0" xyz="0 0 -0.1875"/>
    </collision>
    <inertial>
      <mass value="0.2"/>
      <inertia ixx="0.2" ixy="0.2" ixz="0.2" iyy="0.2" iyz="0.2" izz="0.2"/>
    </inertial>
  </link>
  <link name="right_rear_tibia">
    <visual>
      <geometry>
        <cylinder length="0.2" radius="0.025"/>
      </geometry>
      <origin rpy="0 0 1.57079632679" xyz="0 0 -0.1"/>
    </visual>
    <collision>
      <geometry>
        <sphere radius="0.025"/>
      </geometry>
      <origin rpy="0 0 0" xyz="0 0 -0.1875"/>
    </collision>
    <inertial>
      <mass value="0.2"/>
      <inertia ixx="0.2" ixy="0.2" ixz="0.2" iyy="0.2" iyz="0.2" izz="0.2"/>
    </inertial>
  </link>
  <joint name="right_rear_base_link_to_coxa_joint" type="revolute">
    <parent link="base_link"/>
    <origin rpy="-1.57079632679 0 0" xyz="-0.15                        -0.075                        0"/>
    <child link="right_rear_coxa"/>
    <axis xyz="0 -1 0"/>
    <limit effort="0.2" lower="-0.785398163397" upper="0.785398163397" velocity="0.2"/>
  </joint>
  <joint name="right_rear_coxa_to_femur_joint" type="revolute">
    <parent link="right_rear_coxa"/>
    <origin rpy="0 0 0" xyz="0 0 -0.01"/>
    <child link="right_rear_femur"/>
    <axis xyz="-1 0 0"/>
    <limit effort="0.2" lower="-0.785398163397" upper="0.785398163397" velocity="0.2"/>
  </joint>
  <joint name="right_rear_femur_to_tibia_joint" type="revolute">
    <parent link="right_rear_femur"/>
    <origin rpy="0 0 0" xyz="0 0 -0.2"/>
    <child link="right_rear_tibia"/>
    <axis xyz="-1 0 0"/>
    <limit effort="0.2" lower="-2.35619449019" upper="0.0" velocity="0.2"/>
  </joint>
</robot>

